Workbook

Sheet Cadastro
A1: Amostras LABAS/2020 | B1: Solicitante | C1: Contato | D1: Área | E1: Código Cliente | F1: Entrada | G1: saída | H1: Obs
A2: * | B2: * | C2: * | D2: * | E2: * | F2: * | G2: * | H2: *
A3: Padrão A | B3: - | C3: - | D3: - | E3: - | F3: - | G3: - | H3: -
A4: Padrão B | B4: - | C4: - | D4: - | E4: - | F4: - | G4: - | H4: -
A5: P. Labas A | B5: Padrão | C5: - | D5: - | E5: Padrão A | F5: - | G5: 44726 | H5: -
A6: P. Labas B | B6: - | C6: - | D6: - | E6: Padrão B | F6: - | G6: 44726 | H6: -
A7: 2025/13 | B7: Prof. Elias (Carlos Alberto Faria) | C7: eliasnborges@gmail.com | D7: Greener Hortaliças | E7: Carlos Ace | F7: 45866 | G7: 45890 | H7: -
A8: 2025/14 | C8: eliasnborges@gmail.com | D8: Greener Hortaliças | E8: Carlos Amostra | F8: 45866 | G8: 45890 | H8: -
A9: 2025/15 | B9: Prof. Elias (Rubens Tsuyosh Sato) | C9: eliasnborges@gmail.com | D9: Fazenda Ponte Branca | E9: Rubens alface 1 | F9: 45866 | G9: 45890 | H9: -
A10: 2025/16 | C10: eliasnborges@gmail.com | D10: Fazenda Ponte Branca | E10: Rubens Alface 2 | F10: 45866 | G10: 45890 | H10: -
A11: 2025/17 | C11: eliasnborges@gmail.com | D11: Fazenda Ponte Branca | E11: Rubens Brócolis Y28 | F11: 45866 | G11: 45890 | H11: -
A12: 2025/18 | C12: eliasnborges@gmail.com | D12: Fazenda Ponte Branca | E12: Rubens Couve 1 329 | F12: 45866 | G12: 45890 | H12: -
A13: 2025/19 | B13: CEBUDV | D13: Área 1 | E13: Área 1 0-20 | F13: 45866 | G13: 45890 | H13: -
A14: 2025/20 | D14: Área 2 | E14: Área 1 20-40 | F14: 45866 | G14: 45890 | H14: -
A15: 2025/21 | D15: Área Nova | E15: Área Nova 0-20 | F15: 45866 | G15: 45890 | H15: -
A16: 2025/22 | D16: Área Nova | E16: Área Nova 20-40 | F16: 45866 | G16: 45890 | H16: -

Sheet pH_água
A1: N° | B1: Amostras (código LABAS) | C1: pH_água
A2: * | B2: =Cadastro!A2 -> * | C2: *
A3: 1 | B3: =Cadastro!A3 -> Padrão A | C3: 4.77
A4: 2 | B4: =Cadastro!A4 -> Padrão B | C4: 6.76
A5: 3 | B5: =Cadastro!A5 -> P. Labas A | C5: 4.8073333
A6: 4 | B6: =Cadastro!A6 -> P. Labas B | C6: 6.707907
A7: 5 | B7: =Cadastro!A7 -> 2025/13 | C7: 5.8135194
A8: 6 | B8: =Cadastro!A8 -> 2025/14 | C8: 6.1302817
A9: 7 | B9: =Cadastro!A9 -> 2025/15 | C9: 6.1209651
A10: 8 | B10: =Cadastro!A10 -> 2025/16 | C10: 6.2420801
A11: 9 | B11: =Cadastro!A11 -> 2025/17 | C11: 6.9780866
A12: 10 | B12: =Cadastro!A12 -> 2025/18 | C12: 6.1302817
A13: 11 | B13: =Cadastro!A13 -> 2025/19 | C13: 6.7731227
A14: 12 | B14: =Cadastro!A14 -> 2025/20 | C14: 6.102332
... A16: 14 | B16: =Cadastro!A16 -> 2025/22 | C16: 6.7265401
A166: 165 | B166: =Cadastro!A168 -> 0 | C166: 6.42
A167: 166 | B167: =Cadastro!A169 -> 0 | C167: 6.42
A168: 167 | B168: =Cadastro!A170 -> 0 | C168: 6.42
A169: 168 | B169: =Cadastro!A171 -> 0 | C169: 6.42
A170: 169 | B170: =Cadastro!A172 -> 0 | C170: 6.42
A171: 170 | B171: =Cadastro!A173 -> 0 | C171: 6.42
A172: 171 | B172: =Cadastro!A174 -> 0 | C172: 6.42
A173: 172 | B173: =Cadastro!A175 -> 0 | C173: 6.42
A174: 173 | B174: =Cadastro!A176 -> 0 | C174: 6.42
A175: 174 | B175: =Cadastro!A177 -> 0 | C175: 6.42
A176: 175 | B176: =Cadastro!A178 -> 0 | C176: 6.42
A177: 176 | B177: =Cadastro!A179 -> 0 | C177: 6.42
... A317: 316 | B317: =Cadastro!A319 -> 0 | C317: 6.42

Sheet pH_KCl
A1: N° | B1: Amostras (código LABAS) | C1: pH_KCl
A2: * | B2: =Cadastro!A2 -> * | C2: *
A3: 1 | B3: =Cadastro!A3 -> Padrão A | C3: *
A4: 2 | B4: =Cadastro!A4 -> Padrão B | C4: *
A5: 3 | B5: =Cadastro!A5 -> P. Labas A | C5: *
A6: 4 | B6: =Cadastro!A6 -> P. Labas B | C6: *
A7: 5 | B7: =Cadastro!A7 -> 2025/13 | C7: *
A8: 6 | B8: =Cadastro!A8 -> 2025/14 | C8: *
A9: 7 | B9: =Cadastro!A9 -> 2025/15 | C9: *
A10: 8 | B10: =Cadastro!A10 -> 2025/16 | C10: *
A11: 9 | B11: =Cadastro!A11 -> 2025/17 | C11: *
A12: 10 | B12: =Cadastro!A12 -> 2025/18 | C12: *
A13: 11 | B13: =Cadastro!A13 -> 2025/19 | C13: *
A14: 12 | B14: =Cadastro!A14 -> 2025/20 | C14: *
... A18: 16 | B18: =Cadastro!A18 -> 0 | C18: *

Sheet pH CaCl2
A1: N° | B1: Amostras (código LABAS) | C1: pH_CaCl2
A2: * | B2: =Cadastro!A2 -> * | C2: *
A3: 1 | B3: =Cadastro!A3 -> Padrão A | C3: *
A4: 2 | B4: =Cadastro!A4 -> Padrão B | C4: *
A5: 3 | B5: =Cadastro!A5 -> P. Labas A | C5: *
A6: 4 | B6: =Cadastro!A6 -> P. Labas B | C6: *
A7: 5 | B7: =Cadastro!A7 -> 2025/13 | C7: *
A8: 6 | B8: =Cadastro!A8 -> 2025/14 | C8: *
A9: 7 | B9: =Cadastro!A9 -> 2025/15 | C9: *
A10: 8 | B10: =Cadastro!A10 -> 2025/16 | C10: *
A11: 9 | B11: =Cadastro!A11 -> 2025/17 | C11: *
A12: 10 | B12: =Cadastro!A12 -> 2025/18 | C12: *
A13: 11 | B13: =Cadastro!A13 -> 2025/19 | C13: *
A14: 12 | B14: =Cadastro!A14 -> 2025/20 | C14: *
... A20: 18 | B20: =Cadastro!A20 -> 0 | C20: *

Sheet P_Mehlich1
B1: Determinação de teores disponiveis de P_Mehlich-1
A2: N° | B2: N_Lab | C2: V-solo (dm3) | D2: V-extrator (mL) | E2: Diluição (nx) | F2: Trans(ua) | G2: Abs (u.a) | H2: P-disponivel (mg/dm3) | K2: Curva de Calibração
A3: * | B3: =Cadastro!A2 -> * | F3: * | G3: * | H3: * | K3: P_mg/L | L3: T% | M3: Abs% | N3: x*y
A4: 0 | B4: =Cadastro!A3 -> Padrão A | C4: 0.005 | D4: 50 | E4: 2 | F4: - | G4: - | H4: 0.3 | K4: 0 | L4: 100 | M4: =2-LOG(L4) -> 0 | N4: =K4*M4 -> 0
A5: 0 | B5: =Cadastro!A4 -> Padrão B | C5: 0.005 | D5: 50 | E5: 2 | F5: - | G5: - | H5: 5.7 | K5: 0.4 | L5: 51.1 | M5: =2-LOG(L5) -> 0.2915791 | N5: =K5*M5 -> 0.11663164
A6: 0 | B6: =Cadastro!A5 -> P. Labas A | C6: 0.005 | D6: 50 | E6: 2 | F6: 96.4 | G6: =2-LOG(F6) -> 0.015922966 | H6: =((G6-N19)/N$16)*E6*D6/1000/C6 -> 0.57159491 | K6: 0.8 | L6: 35.7 | M6: =2-LOG(L6) -> 0.44733178 | N6: =K6*M6 -> 0.35786543
A7: 0 | B7: =Cadastro!A6 -> P. Labas B | C7: 0.005 | D7: 50 | E7: 2 | F7: 78.4 | G7: =2-LOG(F7) -> 0.10568394 | H7: =((G7-N20)/N$16)*E7*D7/1000/C7 -> 3.7937907 | K7: 1.2 | L7: 23 | M7: =2-LOG(L7) -> 0.63827216 | N7: =K7*M7 -> 0.7659266
A8: 1 | B8: =Cadastro!A7 -> 2025/13 | C8: 0.005 | D8: 50 | E8: 20 | F8: 41.5 | G8: =2-LOG(F8) -> 0.3819519 | H8: =((G8-N21)/N$16)*E8*D8/1000/C8 -> 137.11124 | K8: 1.6 | L8: 12.5 | M8: =2-LOG(L8) -> 0.90308999 | N8: =K8*M8 -> 1.444944
A9: 2 | B9: =Cadastro!A8 -> 2025/14 | C9: 0.005 | D9: 50 | E9: 20 | F9: 44 | G9: =2-LOG(F9) -> 0.35654732 | H9: =((G9-N22)/N$16)*E9*D9/1000/C9 -> 127.99163 | K9: 2 | L9: 7 | M9: =2-LOG(L9) -> 1.154902 | N9: =K9*M9 -> 2.3098039
A10: 3 | B10: =Cadastro!A9 -> 2025/15 | C10: 0.005 | D10: 50 | E10: 20 | F10: 31.7 | G10: =2-LOG(F10) -> 0.49894074 | H10: =((G10-N23)/N$16)*E10*D10/1000/C10 -> 179.10733 | M10: ∑x.y | N10: =SUM(N4:N9) -> 4.9951716
A11: 4 | B11: =Cadastro!A10 -> 2025/16 | C11: 0.005 | D11: 50 | E11: 20 | F11: 33 | G11: =2-LOG(F11) -> 0.48148606 | H11: =((G11-N24)/N$16)*E11*D11/1000/C11 -> 172.84153
A12: 5 | B12: =Cadastro!A11 -> 2025/17 | C12: 0.005 | D12: 50 | E12: 20 | F12: 24.7 | G12: =2-LOG(F12) -> 0.60730305 | H12: =((G12-N25)/N$16)*E12*D12/1000/C12 -> 218.0067 | K12: ∑x | M12: =SUM(K4:K9) -> 6 | N12: ∑xy | O12: =N10 -> 4.9951716
A13: 6 | B13: =Cadastro!A12 -> 2025/18 | C13: 0.005 | D13: 50 | E13: 20 | F13: 27.4 | G13: =2-LOG(F13) -> 0.56224944 | H13: =((G13-N26)/N$16)*E13*D13/1000/C13 -> 201.83358 | K13: ∑x2 | M13: =K4^2+K5^2+K6^2+K7^2+K8^2+K9^2 -> 8.8 | N13: ȳ | O13: =AVERAGE(M4:M9) -> 0.57252917
A14: 7 | B14: =Cadastro!A13 -> 2025/19 | C14: 0.005 | D14: 50 | E14: 2 | F14: 75.3 | G14: =2-LOG(F14) -> 0.12320502 | H14: =((G14-N27)/N$16)*E14*D14/1000/C14 -> 4.4227542 | K14: (∑x)2 | M14: =SUM(K4:K9)^2 -> 36 | N14: x | O14: =AVERAGE(K4:K9) -> 1
A15: 8 | B15: =Cadastro!A14 -> 2025/20 | C15: 0.005 | D15: 50 | E15: 2 | F15: 88.6 | G15: =2-LOG(F15) -> 0.052566278 | H15: =((G15-N28)/N$16)*E15*D15/1000/C15 -> 1.8869987 | K15: ∑y | M15: =SUM(M4:M9) -> 3.435175
A16: 9 | B16: =Cadastro!A15 -> 2025/21 | C16: 0.005 | D16: 50 | E16: 2 | F16: 61.2 | G16: =2-LOG(F16) -> 0.21324858 | H16: =((G16-N29)/N$16)*E16*D16/1000/C16 -> 7.655094 | M16: b | N16: =(O12-(M12*M15/6))/((M13-(M14/6))) -> 0.55714163
A17: 10 | B17: =Cadastro!A16 -> 2025/22 | C17: 0.005 | D17: 50 | E17: 2 | F17: 63 | G17: =2-LOG(F17) -> 0.20065945 | H17: =((G17-N30)/N$16)*E17*D17/1000/C17 -> 7.2031756 | M17: a | N17: =O13-(N16*O14) -> 0.015387534

Sheet Prem
B1: Determinação de teores disponiveis de P remanescente
A2: N° | B2: N_Lab | C2: Volume solo | D2: Volume Extrator | E2: Diluição (nx) | F2: Trans(ua) | G2: Abs (u.a) | H2: P (mg/L) | K2: Curva de Calibração
A3: * | B3: =Cadastro!A2 -> * | C3: 0.0075 | D3: 75 | E3: 50 | F3: * | G3: * | H3: * | K3: P_mg/L | L3: T% | M3: Abs% | N3: x*y
A4: 1 | B4: =Cadastro!A3 -> Padrão A | C4: 0.0075 | D4: 75 | E4: 50 | F4: - | G4: =2-LOG(F4) -> #VALUE! | H4: 33 | K4: 0 | L4: 99.984 | M4: =2-LOG(L4) -> 6.9492677e-05 | N4: =K4*M4 -> 0
A5: 2 | B5: =Cadastro!A4 -> Padrão B | C5: 0.0075 | D5: 75 | E5: 50 | F5: * | G5: =2-LOG(F5) -> #VALUE! | H5: 22 | K5: 0.3 | L5: 69.056 | M5: =2-LOG(L5) -> 0.16079858 | N5: =K5*M5 -> 0.048239574
A6: 3 | B6: =Cadastro!A5 -> P. Labas A | C6: 0.0075 | D6: 75 | E6: 50 | F6: 40 | G6: =2-LOG(F6) -> 0.39794001 | H6: =(G6-N$17)/N$16*E6 -> 39.792952 | K6: 0.6 | L6: 49.175 | M6: =2-LOG(L6) -> 0.30825563 | N6: =K6*M6 -> 0.18495338
A7: 4 | B7: =Cadastro!A6 -> P. Labas B | C7: 0.0075 | D7: 75 | E7: 50 | F7: * | G7: =2-LOG(F7) -> #VALUE! | H7: =(G7-N$17)/N$16*E7 -> #VALUE! | K7: 0.9 | L7: 43.68 | M7: =2-LOG(L7) -> 0.35971737 | N7: =K7*M7 -> 0.32374563
A8: 5 | B8: =Cadastro!A7 -> 2025/13 | C8: 0.0075 | D8: 75 | E8: 50 | F8: * | G8: =2-LOG(F8) -> #VALUE! | H8: =(G8-N$17)/N$16*E8 -> #VALUE! | K8: 1.2 | L8: 23.037 | M8: =2-LOG(L8) -> 0.63757408 | N8: =K8*M8 -> 0.76508889
A9: 6 | B9: =Cadastro!A8 -> 2025/14 | C9: 0.0075 | D9: 75 | E9: 50 | F9: 30 | G9: =2-LOG(F9) -> 0.52287875 | H9: =(G9-N$17)/N$16*E9 -> 51.979629 | K9: 1.5 | L9: 16.589 | M9: =2-LOG(L9) -> 0.78017979 | N9: =K9*M9 -> 1.1702697
A10: 7 | B10: =Cadastro!A9 -> 2025/15 | C10: 0.0075 | D10: 75 | E10: 50 | F10: 40 | G10: =2-LOG(F10) -> 0.39794001 | H10: =(G10-N$17)/N$16*E10 -> 39.792952 | M10: ∑x.y | N10: =SUM(N4:N9) -> 2.4922972
A11: 8 | B11: =Cadastro!A10 -> 2025/16 | C11: 0.0075 | D11: 75 | E11: 50 | F11: 51.263 | G11: =2-LOG(F11) -> 0.29019598 | H11: =(G11-N$17)/N$16*E11 -> 29.283468
A12: 9 | B12: =Cadastro!A11 -> 2025/17 | C12: 0.0075 | D12: 75 | E12: 50 | F12: 61.038 | G12: =2-LOG(F12) -> 0.21439971 | H12: =(G12-N$17)/N$16*E12 -> 21.890206 | K12: ∑x | M12: =SUM(K4:K9) -> 4.5 | N12: ∑xy | O12: =N10 -> 2.4922972
A13: 10 | K13: ∑x2 | M13: =K4^2+K5^2+K6^2+K7^2+K8^2+K9^2 -> 4.95 | N13: ȳ | O13: =AVERAGE(M4:M9) -> 0.37443249
A14: 11 | K14: (∑x)2 | M14: =SUM(K4:K9)^2 -> 20.25 | N14: x | O14: =AVERAGE(K4:K9) -> 0.75
A15: 12 | K15: ∑y | M15: =SUM(M4:M9) -> 2.2465949
M16: b | N16: =(O12-(M12*M15/6))/((M13-(M14/6))) -> 0.51260378
M17: a | N17: =O13-(N16*O14) -> -0.010020347
M26: EU QUEM INSERIR AS FORMULAS EM Abs%
M27: estava com valores aleatorios

Sheet P_resina
B1: Determinação de teores disponiveis de P_resina
A2: N° | B2: N_Lab | C2: V-solo (dm3) | D2: V-extrator (mL) | E2: Diluição (nx) | F2: Trans(ua) | G2: Abs (u.a) | H2: P-disponivel (mg/dm3) | K2: Curva de Calibração
A3: * | B3: =Cadastro!A2 -> * | H3: * | K3: P_mg/L | L3: trans | M3: Abs | N3: x*y
A4: 1 | B4: =Cadastro!A3 -> Padrão A | C4: 0.0025 | D4: 50 | E4: 1 | F4: * | G4: =2-LOG(F4) -> #VALUE! | H4: =((G4-N$20)/N$19)*E4*D4/1000/C4 -> #VALUE! | K4: 0 | L4: 99.11667 | M4: =2-LOG(L4) -> 0.0038532973 | N4: =K4*M4 -> 0
A5: 2 | B5: =Cadastro!A4 -> Padrão B | C5: 0.0025 | D5: 50 | E5: 1 | F5: * | G5: =2-LOG(F5) -> #VALUE! | H5: =((G5-N$20)/N$19)*E5*D5/1000/C5 -> #VALUE! | K5: 0.8 | L5: 93.175 | M5: =2-LOG(L5) -> 0.030700599 | N5: =K5*M5 -> 0.024560479
A6: 3 | B6: =Cadastro!A5 -> P. Labas A | C6: 0.0025 | D6: 50 | E6: 1 | F6: * | G6: =2-LOG(F6) -> #VALUE! | H6: =((G6-N$20)/N$19)*E6*D6/1000/C6 -> #VALUE! | K6: 1.6 | L6: 87.3 | M6: =2-LOG(L6) -> 0.058985756 | N6: =K6*M6 -> 0.09437721
A7: 4 | B7: =Cadastro!A6 -> P. Labas B | C7: 0.0025 | D7: 50 | E7: 1 | F7: * | G7: =2-LOG(F7) -> #VALUE! | H7: =((G7-N$20)/N$19)*E7*D7/1000/C7 -> #VALUE! | K7: 2.4 | L7: 82.2 | M7: =2-LOG(L7) -> 0.085128182 | N7: =K7*M7 -> 0.20430764
A8: 5 | B8: =Cadastro!A7 -> 2025/13 | C8: 0.0025 | D8: 50 | E8: 1 | F8: 40 | G8: =2-LOG(F8) -> 0.39794001 | H8: =((G8-N$20)/N$19)*E8*D8/1000/C8 -> 219.04025 | K8: 3.2 | L8: 76.5 | M8: =2-LOG(L8) -> 0.11633856 | N8: =K8*M8 -> 0.37228341
A9: 6 | B9: =Cadastro!A8 -> 2025/14 | C9: 0.0025 | D9: 50 | E9: 1 | F9: 30 | G9: =2-LOG(F9) -> 0.52287875 | H9: =((G9-N$20)/N$19)*E9*D9/1000/C9 -> 287.92272 | K9: 4 | L9: 72.425 | M9: =2-LOG(L9) -> 0.1401115 | N9: =K9*M9 -> 0.56044598
A10: 7 | B10: =Cadastro!A9 -> 2025/15 | C10: 0.0025 | D10: 50 | E10: 1 | F10: * | G10: =2-LOG(F10) -> #VALUE! | H10: =((G10-N$20)/N$19)*E10*D10/1000/C10 -> #VALUE! | K10: 4.8 | L10: 67.75 | M10: =2-LOG(L10) -> 0.1690907 | N10: =K10*M10 -> 0.81163536
A11: 8 | B11: =Cadastro!A10 -> 2025/16 | C11: 0.0025 | D11: 50 | E11: 1 | F11: * | G11: =2-LOG(F11) -> #VALUE! | H11: =((G11-N$20)/N$19)*E11*D11/1000/C11 -> #VALUE! | K11: 5.6 | L11: 61.4 | M11: =2-LOG(L11) -> 0.21183163 | N11: =K11*M11 -> 1.1862571
A12: 9 | B12: =Cadastro!A11 -> 2025/17 | C12: 0.0025 | D12: 50 | E12: 1 | F12: * | G12: =2-LOG(F12) -> #VALUE! | H12: =((G12-N$20)/N$19)*E12*D12/1000/C12 -> #VALUE! | K12: 6.4 | L12: 58.275 | M12: =2-LOG(L12) -> 0.23451772 | N12: =K12*M12 -> 1.5009134
A13: 10 | B13: =Cadastro!A12 -> 2025/18 | C13: 0.0025 | D13: 50 | E13: 1 | F13: * | G13: =2-LOG(F13) -> #VALUE! | H13: =((G13-N$20)/N$19)*E13*D13/1000/C13 -> #VALUE! | M13: ∑x.y | N13: =SUM(N4:N12) -> 4.7547806
A14: 11 | B14: =Cadastro!A13 -> 2025/19 | C14: 0.0025 | D14: 50 | E14: 1 | F14: * | G14: =2-LOG(F14) -> #VALUE! | H14: =((G14-N$20)/N$19)*E14*D14/1000/C14 -> #VALUE!
A15: 12 | B15: =Cadastro!A14 -> 2025/20 | C15: 0.0025 | D15: 50 | E15: 1 | F15: * | G15: =2-LOG(F15) -> #VALUE! | H15: =((G15-N$20)/N$19)*E15*D15/1000/C15 -> #VALUE! | K15: ∑x | M15: =SUM(K4:K12) -> 28.8 | N15: ∑xy | O15: =N13 -> 4.7547806
K16: ∑x2 | M16: =K4^2+K5^2+K6^2+K7^2+K8^2+K9^2+K10^2+K11^2+K12^2 -> 130.56 | N16: ȳ | O16: =AVERAGE(M4:M12) -> 0.11672866
K17: (∑x)2 | M17: =SUM(K4:K12)^2 -> 829.44 | N17: x | O17: =AVERAGE(K4:K12) -> 3.2
K18: ∑y | M18: =SUM(M4:M12) -> 1.0505579
M19: b | N19: =(O15-(M15*M18/9))/((M16-(M17/9))) -> 0.036275916
M20: a | N20: =O16-(N19*O17) -> 0.00064572864

Sheet K
B1: Determinação de teores disponiveis de K
A2: N° | B2: N_Lab | C2: V-solo (dm3) | D2: V-extrator (mL) | E2: Diluição (nx) | F2: Emissão (u.a) | G2: K-disponivel (mg/dm3) | J2: Curva de Calibração
A3: * | B3: =Cadastro!A2 -> * | F3: * | G3: * | J3: K_mg/L | K3: Emissão | L3: x*y
A4: 0 | B4: =Cadastro!A3 -> Padrão A | C4: 0.005 | D4: 50 | E4: 1 | F4: - | G4: 7 | J4: 0 | K4: 0 | L4: =J4*K4 -> 0
A5: 0 | B5: =Cadastro!A4 -> Padrão B | C5: 0.005 | D5: 50 | E5: 1 | F5: - | G5: 50 | J5: 4 | K5: 18 | L5: =J5*K5 -> 72
A6: 0 | B6: =Cadastro!A5 -> P. Labas A | C6: 0.005 | D6: 50 | E6: 1 | F6: 2 | G6: =((F6-L$17)/L$16)*E6*D6/1000/C6 -> 1.5108593 | J6: 8 | K6: 48 | L6: =J6*K6 -> 384
A7: 0 | B7: =Cadastro!A6 -> P. Labas B | C7: 0.005 | D7: 50 | E7: 1 | F7: 20 | G7: =((F7-L$17)/L$16)*E7*D7/1000/C7 -> 37.20491 | J7: 12 | K7: 62 | L7: =J7*K7 -> 744
A8: 1 | B8: =Cadastro!A7 -> 2025/13 | C8: 0.005 | D8: 50 | E8: 1 | F8: 27 | G8: =((F8-L$17)/L$16)*E8*D8/1000/C8 -> 51.08593 | J8: 16 | K8: 82 | L8: =J8*K8 -> 1312
A9: 2 | B9: =Cadastro!A8 -> 2025/14 | C9: 0.005 | D9: 50 | E9: 1 | F9: 34 | G9: =((F9-L$17)/L$16)*E9*D9/1000/C9 -> 64.96695 | J9: 20 | K9: 100 | L9: =J9*K9 -> 2000
A10: 3 | B10: =Cadastro!A9 -> 2025/15 | C10: 0.005 | D10: 50 | E10: 1 | F10: 18 | G10: =((F10-L$17)/L$16)*E10*D10/1000/C10 -> 33.238905 | K10: ∑x.y | L10: =SUM(L4:L9) -> 4512
A11: 4 | B11: =Cadastro!A10 -> 2025/16 | C11: 0.005 | D11: 50 | E11: 1 | F11: 62 | G11: =((F11-L$17)/L$16)*E11*D11/1000/C11 -> 120.49103
A12: 5 | B12: =Cadastro!A11 -> 2025/17 | C12: 0.005 | D12: 50 | E12: 1 | F12: 78 | G12: =((F12-L$17)/L$16)*E12*D12/1000/C12 -> 152.21907 | J12: ∑x | K12: =SUM(J4:J9) -> 60 | L12: ∑xy | M12: =L10 -> 4512
A13: 6 | B13: =Cadastro!A12 -> 2025/18 | C13: 0.005 | D13: 50 | E13: 1 | F13: 23 | G13: =((F13-L$17)/L$16)*E13*D13/1000/C13 -> 43.153919 | J13: ∑x2 | K13: =J4^2+J5^2+J6^2+J7^2+J8^2+J9^2 -> 880 | L13: ȳ | M13: =AVERAGE(K4:K9) -> 51.666667
A14: 7 | B14: =Cadastro!A13 -> 2025/19 | C14: 0.005 | D14: 50 | E14: 1 | F14: 53 | G14: =((F14-L$17)/L$16)*E14*D14/1000/C14 -> 102.644 | J14: (∑x)2 | K14: =SUM(J4:J9)^2 -> 3600 | L14: x | M14: =AVERAGE(J4:J9) -> 10
A15: 8 | B15: =Cadastro!A14 -> 2025/20 | C15: 0.005 | D15: 50 | E15: 1 | F15: 48 | G15: =((F15-L$17)/L$16)*E15*D15/1000/C15 -> 92.72899 | J15: ∑y | K15: =SUM(K4:K9) -> 310
A16: 9 | B16: =Cadastro!A15 -> 2025/21 | C16: 0.005 | D16: 50 | E16: 1 | F16: 35 | G16: =((F16-L$17)/L$16)*E16*D16/1000/C16 -> 66.949953 | K16: b | L16: =(M12-(K12*K15/6))/((K13-(K14/6))) -> 5.0428571
A17: 10 | B17: =Cadastro!A16 -> 2025/22 | C17: 0.005 | D17: 50 | E17: 1 | F17: 30 | G17: =((F17-L$17)/L$16)*E17*D17/1000/C17 -> 57.034939 | K17: a | L17: =M13-(L16*M14) -> 1.2380952

Sheet Na
B1: Determinação de teores disponiveis de Na
A2: N° | B2: N_Lab | C2: V-solo (dm3) | D2: V-extrator (mL) | E2: Diluição (nx) | F2: Emissão (u.a) | G2: Na-disponivel (mg/dm3) | J2: Curva de Calibração
A3: * | B3: =Cadastro!A2 -> * | G3: * | J3: Na_mg/L | K3: Emissão | L3: x*y
A4: 1 | B4: =Cadastro!A3 -> Padrão A | C4: 0.005 | D4: 50 | E4: 1 | G4: 0 | J4: 0 | K4: 0 | L4: =J4*K4 -> 0
A5: 2 | B5: =Cadastro!A4 -> Padrão B | C5: 0.005 | D5: 50 | E5: 1 | G5: 3.8 | J5: 20 | K5: 18 | L5: =J5*K5 -> 360
A6: 3 | B6: =Cadastro!A5 -> P. Labas A | C6: 0.005 | D6: 50 | E6: 1 | G6: =((F6-L$17)/L$16)*E6*D6/1000/C6 -> 12.363291 | J6: 40 | K6: 39 | L6: =J6*K6 -> 1560
A7: 4 | B7: =Cadastro!A6 -> P. Labas B | C7: 0.005 | D7: 50 | E7: 1 | G7: =((F7-L$17)/L$16)*E7*D7/1000/C7 -> 12.363291 | J7: 60 | K7: 57 | L7: =J7*K7 -> 3420
A8: 5 | B8: =Cadastro!A7 -> 2025/13 | C8: 0.005 | D8: 50 | E8: 1 | F8: 40 | G8: =((F8-L$17)/L$16)*E8*D8/1000/C8 -> 411.79268 | J8: 80 | K8: 79 | L8: =J8*K8 -> 6320
A9: 6 | B9: =Cadastro!A8 -> 2025/14 | C9: 0.005 | D9: 50 | E9: 1 | F9: 30 | G9: =((F9-L$17)/L$16)*E9*D9/1000/C9 -> 311.93533 | J9: 100 | K9: 100 | L9: =J9*K9 -> 10000
A10: 7 | B10: =Cadastro!A9 -> 2025/15 | C10: 0.005 | D10: 50 | E10: 1 | G10: =((F10-L$17)/L$16)*E10*D10/1000/C10 -> 12.363291 | K10: ∑x.y | L10: =SUM(L4:L9) -> 21660
A11: 8 | B11: =Cadastro!A10 -> 2025/16 | C11: 0.005 | D11: 50 | E11: 1 | G11: =((F11-L$17)/L$16)*E11*D11/1000/C11 -> 12.363291
A12: 9 | B12: =Cadastro!A11 -> 2025/17 | C12: 0.005 | D12: 50 | E12: 1 | G12: =((F12-L$17)/L$16)*E12*D12/1000/C12 -> 12.363291 | J12: ∑x | K12: =SUM(J4:J9) -> 300 | L12: ∑xy | M12: =L10 -> 21660
A13: 10 | B13: =Cadastro!A12 -> 2025/18 | C13: 0.005 | D13: 50 | E13: 1 | G13: =((F13-L$17)/L$16)*E13*D13/1000/C13 -> 12.363291 | J13: ∑x2 | K13: =J4^2+J5^2+J6^2+J7^2+J8^2+J9^2 -> 22000 | L13: ȳ | M13: =AVERAGE(K4:K9) -> 48.833333
A14: 11 | B14: =Cadastro!A13 -> 2025/19 | C14: 0.005 | D14: 50 | E14: 1 | G14: =((F14-L$17)/L$16)*E14*D14/1000/C14 -> 12.363291 | J14: (∑x)2 | K14: =SUM(J4:J9)^2 -> 90000 | L14: x | M14: =AVERAGE(J4:J9) -> 50
A15: 12 | B15: =Cadastro!A14 -> 2025/20 | C15: 0.005 | D15: 50 | E15: 1 | G15: =((F15-L$17)/L$16)*E15*D15/1000/C15 -> 12.363291 | J15: ∑y | K15: =SUM(K4:K9) -> 293
A16: 13 | B16: =Cadastro!A15 -> 2025/21 | C16: 0.005 | D16: 50 | E16: 1 | G16: =((F16-L$17)/L$16)*E16*D16/1000/C16 -> 12.363291 | K16: b | L16: =(M12-(K12*K15/6))/((K13-(K14/6))) -> 1.0014286
A17: 14 | B17: =Cadastro!A16 -> 2025/22 | C17: 0.005 | D17: 50 | E17: 1 | G17: =((F17-L$17)/L$16)*E17*D17/1000/C17 -> 12.363291 | K17: a | L17: =M13-(L16*M14) -> -1.2380952
A18: 15 | B18: =Cadastro!A17 -> 0 | C18: 0.005 | D18: 50 | E18: 1 | G18: =((F18-L$17)/L$16)*E18*D18/1000/C18 -> 12.363291
Q30: esta errada

Sheet Al³
B1: Determinação de teores acidez trocável (Al3+)
A2: N° | B2: N_Lab | C2: Acidez trocável (cmolc/dm3) | D2: resultado
A3: * | B3: Branco | C3: 0.05 | F3: no aluminio vao ser inseridos 2 valores
A4: 1 | B4: =Cadastro!A3 -> Padrão A | C4: 0.41 | F4: valor coluna-branco
A5: 2 | B5: =Cadastro!A4 -> Padrão B | C5: 0
A6: 3 | B6: =Cadastro!A5 -> P. Labas A | C6: 0.39 | D6: =C6-C$3 -> 0.34
A7: 4 | B7: =Cadastro!A6 -> P. Labas B | C7: 0.5 | D7: =C7-C$3 -> 0.45
A8: 5 | B8: =Cadastro!A7 -> 2025/13 | C8: 0.48 | D8: =C8-C$3 -> 0.43
A9: 6 | B9: =Cadastro!A8 -> 2025/14 | C9: 0 | D9: =C9-C$3 -> -0.05
A10: 7 | B10: =Cadastro!A9 -> 2025/15 | C10: 0 | D10: =C10-C$3 -> -0.05
A11: 8 | B11: =Cadastro!A10 -> 2025/16 | C11: 0 | D11: =C11-C$3 -> -0.05
A12: 9 | B12: =Cadastro!A11 -> 2025/17 | C12: 0 | D12: =C12-C$3 -> -0.05
A13: 10 | B13: =Cadastro!A12 -> 2025/18 | C13: 0 | D13: =C13-C$3 -> -0.05
A14: 11 | B14: =Cadastro!A13 -> 2025/19 | C14: 0 | D14: =C14-C$3 -> -0.05
A15: 12 | B15: =Cadastro!A14 -> 2025/20 | C15: 0 | D15: =C15-C$3 -> -0.05
A16: 13 | B16: =Cadastro!A15 -> 2025/21 | C16: 0 | D16: =C16-C$3 -> -0.05
A17: 14 | B17: =Cadastro!A16 -> 2025/22 | C17: 0 | D17: =C17-C$3 -> -0.05

Sheet H + Al
B1: Determinação de teores de H+Al Acetato de Cálcio | F1: acidez potencial
A2: N° | B2: N_Lab | C2: H+Al | D2: resultado
A3: * | B3: Branco | C3: 0.05 | D3: col c - branco
A4: 1 | B4: =Cadastro!A3 -> Padrão A | C4: 2.8
A5: 2 | B5: =Cadastro!A4 -> Padrão B | C5: 2.9
A6: 3 | B6: =Cadastro!A5 -> P. Labas A | C6: 1.2123555 | D6: =C6-C$3 -> 1.1623555
A7: 4 | B7: =Cadastro!A6 -> P. Labas B | C7: 1.4718719 | D7: =C7-C$3 -> 1.4218719
A8: 5 | B8: =Cadastro!A7 -> 2025/13 | C8: 1.4718719 | D8: =C8-C$3 -> 1.4218719
A9: 6 | B9: =Cadastro!A8 -> 2025/14 | C9: 0.49433345 | D9: =C9-C$3 -> 0.44433345
A10: 7 | B10: =Cadastro!A9 -> 2025/15 | C10: 0.84271359 | D10: =C10-C$3 -> 0.79271359
A11: 8 | B11: =Cadastro!A10 -> 2025/16 | C11: 0.82252669 | D11: =C11-C$3 -> 0.77252669
A12: 9 | B12: =Cadastro!A11 -> 2025/17 | C12: 0.50646566 | D12: =C12-C$3 -> 0.45646566
A13: 10 | B13: =Cadastro!A12 -> 2025/18 | C13: 0.84271359 | D13: =C13-C$3 -> 0.79271359
A14: 11 | B14: =Cadastro!A13 -> 2025/19 | C14: 0.58577388 | D14: =C14-C$3 -> 0.53577388
A15: 12 | B15: =Cadastro!A14 -> 2025/20 | C15: 0.88458587 | D15: =C15-C$3 -> 0.83458587
A16: 13 | B16: =Cadastro!A15 -> 2025/21 | C16: 1.183314 | D16: =C16-C$3 -> 1.133314
A17: 14 | B17: =Cadastro!A16 -> 2025/22 | C17: 1.2725944 | D17: =C17-C$3 -> 1.2225944

Sheet B
B1: Determinação de teores disponiveis de Boro
A2: N° | B2: N_Lab | C2: V-solo (dm3) | D2: V-extrator (mL) | E2: Diluição (nx) | F2: Trans(ua) | G2: Abs (u.a) | H2: B-disponivel (mg/dm3) | K2: Curva de Calibração
A3: * | B3: =Cadastro!A2 -> * | C3: 0.01 | D3: 20 | E3: 1.5 | F3: * | G3: * | H3: * | K3: B_mg/L | L3: T% | M3: Abs% | N3: x*y
A4: 1 | B4: =Cadastro!A3 -> Padrão A | C4: 0.01 | D4: 20 | E4: 1.5 | F4: - | G4: - | H4: 0.31 | K4: 0 | L4: 99.997 | M4: =2-LOG(L4) -> 1.302903e-05 | N4: =K4*M4 -> 0
A5: 2 | B5: =Cadastro!A4 -> Padrão B | C5: 0.01 | D5: 20 | E5: 1.5 | F5: 91 | G5: - | H5: 0.94 | K5: 0.2 | L5: 69.024 | M5: =2-LOG(L5) -> 0.16099988 | N5: =K5*M5 -> 0.032199975
A6: 3 | B6: =Cadastro!A5 -> P. Labas A | C6: 0.01 | D6: 20 | E6: 1.5 | F6: 99.6 | G6: =2-LOG(F6) -> 0.0017406616 | H6: =((G6)/N$16)*E6*D6/1000/C6 -> 0.0079106241 | K6: 0.4 | L6: 48.65 | M6: =2-LOG(L6) -> 0.31291716 | N6: =K6*M6 -> 0.12516686
A7: 4 | B7: =Cadastro!A6 -> P. Labas B | C7: 0.01 | D7: 20 | E7: 1.5 | F7: 86.4 | G7: =2-LOG(F7) -> 0.063486258 | H7: =((G7)/N$16)*E7*D7/1000/C7 -> 0.28852014 | K7: 0.6 | L7: 38.369 | M7: =2-LOG(L7) -> 0.41601952 | N7: =K7*M7 -> 0.24961171
A8: 5 | B8: =Cadastro!A7 -> 2025/13 | C8: 0.01 | D8: 20 | E8: 1.5 | F8: 96.7 | G8: =2-LOG(F8) -> 0.014573526 | H8: =((G8)/N$16)*E8*D8/1000/C8 -> 0.066230959 | K8: 0.8 | L8: 27.854 | M8: =2-LOG(L8) -> 0.55511243 | N8: =K8*M8 -> 0.44408994
A9: 6 | B9: =Cadastro!A8 -> 2025/14 | C9: 0.01 | D9: 20 | E9: 1.5 | F9: 97.8 | G9: =2-LOG(F9) -> 0.0096611452 | H9: =((G9)/N$16)*E9*D9/1000/C9 -> 0.043906115 | K9: 1 | L9: 21.523 | M9: =2-LOG(L9) -> 0.66709719 | N9: =K9*M9 -> 0.66709719
A10: 8 | B10: =Cadastro!A9 -> 2025/15 | C10: 0.01 | D10: 20 | E10: 1.5 | F10: 98.2 | G10: =2-LOG(F10) -> 0.0078885122 | H10: =((G10)/N$16)*E10*D10/1000/C10 -> 0.035850194 | M10: ∑x.y | N10: =SUM(N4:N9) -> 1.5181657
A11: 9 | B11: =Cadastro!A10 -> 2025/16 | C11: 0.01 | D11: 20 | E11: 1.5 | F11: 95.5 | G11: =2-LOG(F11) -> 0.019996628 | H11: =((G11)/N$16)*E11*D11/1000/C11 -> 0.090876832
A12: 10 | B12: =Cadastro!A11 -> 2025/17 | C12: 0.01 | D12: 20 | E12: 1.5 | F12: 94.4 | G12: =2-LOG(F12) -> 0.025028006 | H12: =((G12)/N$16)*E12*D12/1000/C12 -> 0.11374247 | K12: ∑x | M12: =SUM(K4:K9) -> 3 | N12: ∑xy | O12: =N10 -> 1.5181657
A13: 11 | B13: =Cadastro!A12 -> 2025/18 | C13: 0.01 | D13: 20 | E13: 1.5 | F13: 96.8 | G13: =2-LOG(F13) -> 0.014124643 | H13: =((G13)/N$16)*E13*D13/1000/C13 -> 0.064190961 | K13: ∑x2 | M13: =K4^2+K5^2+K6^2+K7^2+K8^2+K9^2 -> 2.2 | N13: ȳ | O13: =AVERAGE(M4:M9) -> 0.35202653
A14: 12 | B14: =Cadastro!A13 -> 2025/19 | C14: 0.01 | D14: 20 | E14: 1.5 | F14: 96.8 | G14: =2-LOG(F14) -> 0.014124643 | H14: =((G14)/N$16)*E14*D14/1000/C14 -> 0.064190961 | K14: (∑x)2 | M14: =SUM(K4:K9)^2 -> 9 | N14: x | O14: =AVERAGE(K4:K9) -> 0.5
A15: 13 | B15: =Cadastro!A14 -> 2025/20 | C15: 0.01 | D15: 20 | E15: 1.5 | F15: 96.7 | G15: =2-LOG(F15) -> 0.014573526 | H15: =((G15)/N$16)*E15*D15/1000/C15 -> 0.066230959 | K15: ∑y | M15: =SUM(M4:M9) -> 2.1121592
A16: 14 | B16: =Cadastro!A15 -> 2025/21 | C16: 0.01 | D16: 20 | E16: 1.5 | F16: 95.3 | G16: =2-LOG(F16) -> 0.020907099 | H16: =((G16)/N$16)*E16*D16/1000/C16 -> 0.095014566 | M16: b | N16: =(O12-(M12*M15/6))/((M13-(M14/6))) -> 0.66012298
A17: 15 | B17: =Cadastro!A16 -> 2025/22 | C17: 0.01 | D17: 20 | E17: 1.5 | F17: 94.1 | G17: =2-LOG(F17) -> 0.026410377 | H17: =((G17)/N$16)*E17*D17/1000/C17 -> 0.1200248 | M17: a | N17: =O13-(N16*O14) -> 0.021965045

Sheet S
B1: Determinação de teores disponiveis de Enxofre (S)
A2: N° | B2: N_Lab | C2: V-solo (dm3) | D2: V-extrator (mL) | E2: Diluição (nx) | F2: Trans(ua) | G2: Abs (u.a) | H2: S-disponivel (mg/dm3) | K2: Curva de Calibração
A3: * | B3: =Cadastro!A2 -> * | C3: 0.01 | D3: 25 | E3: 1.15 | F3: * | G3: * | H3: * | K3: S_mg/L | L3: T% | M3: Abs% | N3: x*y
A4: 1 | B4: =Cadastro!A3 -> Padrão A | C4: 0.01 | D4: 25 | E4: 1.15 | F4: - | G4: - | H4: 20.2 | K4: 0 | L4: 99.983 | M4: =2-LOG(L4) -> 7.3836338e-05 | N4: =K4*M4 -> 0
A5: 2 | B5: =Cadastro!A4 -> Padrão B | C5: 0.01 | D5: 25 | E5: 1.15 | F5: - | G5: - | H5: 0.3 | K5: 0.3 | L5: 96.825 | M5: =2-LOG(L5) -> 0.014012494 | N5: =K5*M5 -> 0.0042037483
A6: 3 | B6: =Cadastro!A5 -> P. Labas A | C6: 0.01 | D6: 25 | E6: 1.15 | F6: 71.7 | G6: =2-LOG(F6) -> 0.14448084 | H6: =((G6-N$21)/N$20)*E6*D6/1000/C6 -> 24.791177 | K6: 0.6 | L6: 93.107 | M6: =2-LOG(L6) -> 0.031017667 | N6: =K6*M6 -> 0.0186106
A7: 4 | B7: =Cadastro!A6 -> P. Labas B | C7: 0.01 | D7: 25 | E7: 1.15 | F7: 98.4 | G7: =2-LOG(F7) -> 0.0070049016 | H7: =((G7)/N$20)*E7*D7/1000/C7 -> 1.3318784 | K7: 0.9 | L7: 92.877 | M7: =2-LOG(L7) -> 0.032091821 | N7: =K7*M7 -> 0.028882639
A8: 5 | B8: =Cadastro!A7 -> 2025/13 | C8: 0.01 | D8: 25 | E8: 1.15 | F8: 85.5 | G8: =2-LOG(F8) -> 0.068033885 | H8: =((G8)/N$20)*E8*D8/1000/C8 -> 12.935637 | K8: 1.2 | L8: 90.861 | M8: =2-LOG(L8) -> 0.041622488 | N8: =K8*M8 -> 0.049946985
A9: 6 | B9: =Cadastro!A8 -> 2025/14 | C9: 0.01 | D9: 25 | E9: 1.15 | F9: 98.5 | G9: =2-LOG(F9) -> 0.0065637695 | H9: =((G9)/N$20)*E9*D9/1000/C9 -> 1.2480037 | K9: 2 | L9: 88.499 | M9: =2-LOG(L9) -> 0.053061637 | N9: =K9*M9 -> 0.10612327
A10: 7 | B10: =Cadastro!A9 -> 2025/15 | C10: 0.01 | D10: 25 | E10: 1.15 | F10: 99.1 | G10: =2-LOG(F10) -> 0.0039263455 | H10: =((G10)/N$20)*E10*D10/1000/C10 -> 0.74653652 | K10: 4 | L10: 85.098 | M10: =2-LOG(L10) -> 0.070080647 | N10: =K10*M10 -> 0.28032259
A11: 8 | B11: =Cadastro!A10 -> 2025/16 | C11: 0.01 | D11: 25 | E11: 1.15 | F11: 99.7 | G11: =2-LOG(F11) -> 0.0013048417 | H11: =((G11)/N$20)*E11*D11/1000/C11 -> 0.24809635 | K11: 6 | L11: 80.264 | M11: =2-LOG(L11) -> 0.095479201 | N11: =K11*M11 -> 0.5728752
A12: 9 | B12: =Cadastro!A11 -> 2025/17 | C12: 0.01 | D12: 25 | E12: 1.15 | F12: 93.2 | G12: =2-LOG(F12) -> 0.030584088 | H12: =((G12-N$21)/N$20)*E12*D12/1000/C12 -> 3.1353936 | K12: 8 | L12: 74.704 | M12: =2-LOG(L12) -> 0.12665614 | N12: =K12*M12 -> 1.0132491
A13: 10 | B13: =Cadastro!A12 -> 2025/18 | C13: 0.01 | D13: 25 | E13: 1.15 | F13: 69.1 | G13: =2-LOG(F13) -> 0.16052195 | H13: =((G13-N$21)/N$20)*E13*D13/1000/C13 -> 27.841157 | K13: 10 | L13: 66.707 | M13: =2-LOG(L13) -> 0.17582859 | N13: =K13*M13 -> 1.7582859
A14: 11 | B14: =Cadastro!A13 -> 2025/19 | C14: 0.01 | D14: 25 | E14: 1.15 | F14: 99.5 | G14: =2-LOG(F14) -> 0.0021769193 | H14: =((G14)/N$20)*E14*D14/1000/C14 -> 0.413909 | M14: ∑x.y | N14: =SUM(N4:N13) -> 3.8325001
A15: 12 | B15: =Cadastro!A14 -> 2025/20 | C15: 0.01 | D15: 25 | E15: 1.15 | F15: 99.7 | G15: =2-LOG(F15) -> 0.0013048417 | H15: =((G15)/N$20)*E15*D15/1000/C15 -> 0.24809635
A16: 13 | B16: =Cadastro!A15 -> 2025/21 | C16: 0.01 | D16: 25 | E16: 1.15 | F16: 86.5 | G16: =2-LOG(F16) -> 0.062983893 | H16: =((G16-N$21)/N$20)*E16*D16/1000/C16 -> 9.2957373 | K16: ∑x | M16: =SUM(K4:K13) -> 33 | N16: ∑xy | O16: =N14 -> 3.8325001
A17: 14 | B17: =Cadastro!A16 -> 2025/22 | C17: 0.01 | D17: 25 | E17: 1.15 | F17: 89.4 | G17: =2-LOG(F17) -> 0.048662481 | H17: =((G17-N$21)/N$20)*E17*D17/1000/C17 -> 6.5727327 | K17: ∑x2 | M17: =K4^2+K5^2+K6^2+K7^2+K8^2+K9^2+K10^2+K11^2+K12^2+K13^2 -> 222.7 | N17: ȳ | O17: =AVERAGE(M4:M13) -> 0.063992452
K18: (∑x)2 | M18: =SUM(K4:K13)^2 -> 1089 | N18: x | O18: =AVERAGE(K4:K13) -> 3.3
K19: ∑y | M19: =SUM(M4:M13) -> 0.63992452
M20: b | N20: =(O16-(M16*M19/10))/((M17-(M18/10))) -> 0.015120819
M21: a | N21: =O17-(N20*O18) -> 0.014093751

Sheet M.O
B1: Determinação de teores disponiveis de Matéria orgânica | K1: dag/kg | L1: Abs | M1: MOS(dag/kg)
A2: N° | B2: N_Lab | C2: V-solo (dm3) | D2: V-extrator (mL) | E2: Diluição (nx) | F2: Trans(ua) | G2: Abs (u.a) | H2: MO-disponivel (dag/kg)) | K2: 2.3 | L2: 0.15365051 | M2: =(L2+0.0136)/0.0729 -> 2.2942457
A3: * | B3: =Cadastro!A2 -> * | K3: 2.2 | L3: 0.14935376 | M3: =(L3+0.0136)/0.0729 -> 2.2353054
A4: 0 | B4: =Cadastro!A3 -> Padrão A | C4: 0.001 | D4: 10 | E4: 6 | F4: - | G4: - | H4: 0.9 | K4: 2.2 | L4: 0.14677649 | M4: =(L4+0.0136)/0.0729 -> 2.1999518
A5: 0 | B5: =Cadastro!A4 -> Padrão B | C5: 0.001 | D5: 10 | E5: 6 | F5: 80.5 | G5: =2-LOG(F5) -> 0.09420412 | H5: 8.07 | K5: 2.2 | L5: 0.14523864 | M5: =(L5+0.0136)/0.0729 -> 2.1788566
A6: 0 | B6: =Cadastro!A5 -> P. Labas A | C6: 0.001 | D6: 10 | E6: 6 | F6: 93.4 | G6: =2-LOG(F6) -> 0.029653124 | H6: =(G6+0.0136)/0.0729 -> 0.59332131 | K6: 2.1 | L6: 0.13846559 | M6: =(L6+0.0136)/0.0729 -> 2.0859477
A7: 0 | B7: =Cadastro!A6 -> P. Labas B | C7: 0.001 | D7: 10 | E7: 6 | F7: 63.7 | G7: =2-LOG(F7) -> 0.19586057 | H7: =(G7+0.0136)/0.0729 -> 2.8732588 | K7: 2 | L7: 0.13430394 | M7: =(L7+0.0136)/0.0729 -> 2.0288606
A8: 1 | B8: =Cadastro!A7 -> 2025/13 | C8: 0.001 | D8: 10 | E8: 6 | F8: 87.4 | G8: =2-LOG(F8) -> 0.058488567 | H8: =(G8+0.0136)/0.0729 -> 0.98886924 | K8: 2 | L8: 0.13243824 | M8: =(L8+0.0136)/0.0729 -> 2.003268
A9: 2 | B9: =Cadastro!A8 -> 2025/14 | C9: 0.001 | D9: 10 | E9: 6 | F9: 91.7 | G9: =2-LOG(F9) -> 0.037630664 | H9: =(G9+0.0136)/0.0729 -> 0.7027526 | K9: 2 | L9: 0.1304808 | M9: =(L9+0.0136)/0.0729 -> 1.976417
A10: 3 | B10: =Cadastro!A9 -> 2025/15 | C10: 0.001 | D10: 10 | E10: 6 | F10: 93 | G10: =2-LOG(F10) -> 0.031517051 | H10: =(G10+0.0136)/0.0729 -> 0.61888959 | K10: 1.9 | L10: 0.12493874 | M10: =(L10+0.0136)/0.0729 -> 1.9003942
A11: 4 | B11: =Cadastro!A10 -> 2025/16 | C11: 0.001 | D11: 10 | E11: 6 | F11: 90.4 | G11: =2-LOG(F11) -> 0.04383157 | H11: =(G11+0.0136)/0.0729 -> 0.78781303 | K11: 1.8 | L11: 0.12057723 | M11: =(L11+0.0136)/0.0729 -> 1.8405656
A12: 5 | B12: =Cadastro!A11 -> 2025/17 | C12: 0.001 | D12: 10 | E12: 6 | F12: 90.7 | G12: =2-LOG(F12) -> 0.042392713 | H12: =(G12+0.0136)/0.0729 -> 0.76807562 | K12: 1.8 | L12: 0.1170829 | M12: =(L12+0.0136)/0.0729 -> 1.7926323
A13: 6 | B13: =Cadastro!A12 -> 2025/18 | C13: 0.001 | D13: 10 | E13: 6 | F13: 93.8 | G13: =2-LOG(F13) -> 0.027797162 | H13: =(G13+0.0136)/0.0729 -> 0.5678623 | K13: 1.8 | L13: 0.11627045 | M13: =(L13+0.0136)/0.0729 -> 1.7814876
A14: 7 | B14: =Cadastro!A13 -> 2025/19 | C14: 0.001 | D14: 10 | E14: 6 | F14: 87.8 | G14: =2-LOG(F14) -> 0.056505484 | H14: =(G14+0.0136)/0.0729 -> 0.96166645 | K14: 1.6 | L14: 0.10513034 | M14: =(L14+0.0136)/0.0729 -> 1.6286741
A15: 8 | B15: =Cadastro!A14 -> 2025/20 | C15: 0.001 | D15: 10 | E15: 6 | F15: 96.3 | G15: =2-LOG(F15) -> 0.016373713 | H15: =(G15+0.0136)/0.0729 -> 0.41116204 | K15: 1.6 | L15: 0.10434545 | M15: =(L15+0.0136)/0.0729 -> 1.6179074
A16: 9 | B16: =Cadastro!A15 -> 2025/21 | C16: 0.001 | D16: 10 | E16: 6 | F16: 63.8 | G16: =2-LOG(F16) -> 0.19517932 | H16: =(G16+0.0136)/0.0729 -> 2.8639139 | K16: 1.6 | L16: 0.10282393 | M16: =(L16+0.0136)/0.0729 -> 1.5970361
A17: 10 | B17: =Cadastro!A16 -> 2025/22 | C17: 0.001 | D17: 10 | E17: 6 | F17: 72.8 | G17: =2-LOG(F17) -> 0.13786862 | H17: =(G17+0.0136)/0.0729 -> 2.0777589 | K17: 1.4 | L17: 0.086101415 | M17: =(L17+0.0136)/0.0729 -> 1.3676463
K18: 1.3 | L18: 0.079354999 | M18: =(L18+0.0136)/0.0729 -> 1.2751029
K19: 1.2 | L19: 0.076787078 | M19: =(L19+0.0136)/0.0729 -> 1.2398776
K20: 1.34 | L20: 0.076238039 | M20: =(L20+0.0136)/0.0729 -> 1.2323462
K21: 1.2 | L21: 0.075756907 | M21: =(L21+0.0136)/0.0729 -> 1.2257463
K22: 1.2 | L22: 0.072835026 | M22: =(L22+0.0136)/0.0729 -> 1.1856656
K23: 1.1 | L23: 0.066022004 | M23: =(L23+0.0136)/0.0729 -> 1.0922086
K24: 1 | L24: 0.062617533 | M24: =(L24+0.0136)/0.0729 -> 1.045508
K25: 0.9 | L25: 0.051895258 | M25: =(L25+0.0136)/0.0729 -> 0.89842603
K26: 0.8 | L26: 0.04523665 | M26: =(L26+0.0136)/0.0729 -> 0.8070871

Sheet Ca2+
B1: Determinação de teores disponiveis de Ca_KCl
A2: N° | B2: N_Lab | C2: V-solo (dm3) | D2: V-extrator (mL) | E2: Diluição (nx) | F2: Abs (u.a) | G2: Ca-disponivel (cmolc/dm3) | J2: Curva de Calibração
A3: * | B3: =Cadastro!A2 -> * | J3: Ca_mg/L | K3: trans | L3: Abs | M3: x*y
A4: 1 | B4: =Cadastro!A3 -> Padrão A | C4: 0.005 | D4: 50 | E4: 10 | F4: - | G4: 0 | J4: 0 | L4: -0.0002 | M4: =J4*L4 -> 0
A5: 2 | B5: =Cadastro!A4 -> Padrão B | C5: 0.005 | D5: 50 | E5: 10 | F5: - | G5: 4.75 | J5: 1 | L5: 0.0639 | M5: =J5*L5 -> 0.0639
A6: 3 | B6: =Cadastro!A5 -> P. Labas A | C6: 0.005 | D6: 50 | E6: 10 | F6: 0.0094 | G6: =((F6)/M$17)*E6*D6/1000/200/C6 -> 0.11530887 | J6: 2 | L6: 0.1086 | M6: =J6*L6 -> 0.2172
A7: 4 | B7: =Cadastro!A6 -> P. Labas B | C7: 0.005 | D7: 50 | E7: 10 | F7: 0.4264 | G7: =((F7-M$18)/M$17)*E7*D7/1000/200/C7 -> 4.965361 | J7: 4 | L7: 0.1959 | M7: =J7*L7 -> 0.7836
A8: 5 | B8: =Cadastro!A7 -> 2025/13 | C8: 0.005 | D8: 50 | E8: 10 | F8: 0.1731 | G8: =((F8-M$18)/M$17)*E8*D8/1000/200/C8 -> 1.8581551 | J8: 8 | L8: 0.3621 | M8: =J8*L8 -> 2.8968
A9: 6 | B9: =Cadastro!A8 -> 2025/14 | C9: 0.005 | D9: 50 | E9: 10 | F9: 0.2296 | G9: =((F9-M$18)/M$17)*E9*D9/1000/200/C9 -> 2.5512349 | J9: 16 | L9: 0.663 | M9: =J9*L9 -> 10.608
A10: 7 | B10: =Cadastro!A9 -> 2025/15 | C10: 0.005 | D10: 50 | E10: 10 | F10: 0.2327 | G10: =((F10-M$18)/M$17)*E10*D10/1000/200/C10 -> 2.5892623
A11: 8 | B11: =Cadastro!A10 -> 2025/16 | C11: 0.005 | D11: 50 | E11: 10 | F11: 0.256 | G11: =((F11-M$18)/M$17)*E11*D11/1000/200/C11 -> 2.8750811 | L11: ∑x.y | M11: =SUM(M4:M10) -> 14.5695
A12: 9 | B12: =Cadastro!A11 -> 2025/17 | C12: 0.005 | D12: 50 | E12: 10 | F12: 0.3285 | G12: =((F12-M$18)/M$17)*E12*D12/1000/200/C12 -> 3.7644314
A13: 10 | B13: =Cadastro!A12 -> 2025/18 | C13: 0.005 | D13: 50 | E13: 10 | F13: 0.2717 | G13: =((F13-M$18)/M$17)*E13*D13/1000/200/C13 -> 3.0676715 | J13: ∑x | L13: =SUM(J4:J10) -> 31 | M13: ∑xy | N13: =M11 -> 14.5695
A14: 11 | B14: =Cadastro!A13 -> 2025/19 | C14: 0.005 | D14: 50 | E14: 10 | F14: 0.3989 | G14: =((F14-M$18)/M$17)*E14*D14/1000/200/C14 -> 4.6280212 | J14: ∑x2 | L14: =J4^2+J5^2+J6^2+J7^2+J8^2+J9^2+J10^2 -> 341 | M14: ȳ | N14: =AVERAGE(L4:L10) -> 0.23221667
A15: 12 | B15: =Cadastro!A14 -> 2025/20 | C15: 0.005 | D15: 50 | E15: 10 | F15: 0.2396 | G15: =((F15-M$18)/M$17)*E15*D15/1000/200/C15 -> 2.6739039 | J15: (∑x)2 | L15: =SUM(J4:J10)^2 -> 961 | M15: x | N15: =AVERAGE(J4:J10) -> 5.1666667
A16: 13 | B16: =Cadastro!A15 -> 2025/21 | C16: 0.005 | D16: 50 | E16: 10 | F16: 0.874 | G16: =((F16-M$18)/M$17)*E16*D16/1000/200/C16 -> 10.456026 | J16: ∑y | L16: =SUM(L4:L10) -> 1.3933
A17: 14 | B17: =Cadastro!A16 -> 2025/22 | C17: 0.005 | D17: 50 | E17: 10 | F17: 0.7444 | G17: =((F17-M$18)/M$17)*E17*D17/1000/200/C17 -> 8.8662354 | L17: b | M17: =(N13-(L13*L16/6))/((L14-(L15/6))) -> 0.040760092
L18: a | M18: =N14-(M17*N15) -> 0.021622857
I29: 1 curva de calibracao
I30: 2 absorcao atomica
I31: 3 abs

Sheet Mg²
B1: Determinação de teores disponiveis de Mg²+
A2: N° | B2: N_Lab | C2: V-solo (dm3) | D2: V-extrator (mL) | E2: Diluição (nx) | F2: Abs (u.a) | G2: Mg-disponivel (Cmolc/dm3) | J2: Curva de Calibração
A3: * | B3: =Cadastro!A2 -> * | J3: Mg_mg/L | K3: trans | L3: Abs | M3: x*y
A4: 1 | B4: =Cadastro!A3 -> Padrão A | C4: 0.005 | D4: 50 | E4: 10 | F4: 0.0255 | G4: 0 | J4: 0 | L4: 0 | M4: =J4*L4 -> 0
A5: 2 | B5: =Cadastro!A4 -> Padrão B | C5: 0.005 | D5: 50 | E5: 10 | F5: 0.0081 | G5: 1.28 | J5: 0.5 | L5: 0.0484 | M5: =J5*L5 -> 0.0242
A6: 3 | B6: =Cadastro!A5 -> P. Labas A | C6: 0.005 | D6: 50 | E6: 10 | F6: 0.0022 | G6: =((F6)/M$17)*E6*D6/1000/C6/120 -> 0.034236241 | J6: 1 | L6: 0.0831 | M6: =J6*L6 -> 0.0831
A7: 4 | B7: =Cadastro!A6 -> P. Labas B | C7: 0.005 | D7: 50 | E7: 10 | F7: 0.0999 | G7: =((F7-M$18)/M$17)*E7*D7/1000/C7/120 -> 1.1578519 | J7: 2 | L7: 0.1497 | M7: =J7*L7 -> 0.2994
A8: 5 | B8: =Cadastro!A7 -> 2025/13 | C8: 0.005 | D8: 50 | E8: 10 | F8: 0.0547 | G8: =((F8-M$18)/M$17)*E8*D8/1000/C8/120 -> 0.45445275 | J8: 4 | L8: 0.2652 | M8: =J8*L8 -> 1.0608
A9: 6 | B9: =Cadastro!A8 -> 2025/14 | C9: 0.005 | D9: 50 | E9: 10 | F9: 0.0457 | G9: =((F9-M$18)/M$17)*E9*D9/1000/C9/120 -> 0.3143954 | J9: 8 | L9: 0.4366 | M9: =J9*L9 -> 3.4928
A10: 7 | B10: =Cadastro!A9 -> 2025/15 | C10: 0.005 | D10: 50 | E10: 10 | F10: 0.0404 | G10: =((F10-M$18)/M$17)*E10*D10/1000/C10/120 -> 0.23191718
A11: 8 | B11: =Cadastro!A10 -> 2025/16 | C11: 0.005 | D11: 50 | E11: 10 | F11: 0.0488 | G11: =((F11-M$18)/M$17)*E11*D11/1000/C11/120 -> 0.36263738 | L11: ∑x.y | M11: =SUM(M4:M10) -> 4.9603
A12: 9 | B12: =Cadastro!A11 -> 2025/17 | C12: 0.005 | D12: 50 | E12: 10 | F12: 0.0603 | G12: =((F12-M$18)/M$17)*E12*D12/1000/C12/120 -> 0.54159954
A13: 10 | B13: =Cadastro!A12 -> 2025/18 | C13: 0.005 | D13: 50 | E13: 10 | F13: 0.0344 | G13: =((F13-M$18)/M$17)*E13*D13/1000/C13/120 -> 0.13854562 | J13: ∑x | L13: =SUM(J4:J10) -> 15.5 | M13: ∑xy | N13: =M11 -> 4.9603
A14: 11 | B14: =Cadastro!A13 -> 2025/19 | C14: 0.005 | D14: 50 | E14: 10 | F14: 0.0734 | G14: =((F14-M$18)/M$17)*E14*D14/1000/C14/120 -> 0.74546079 | J14: ∑x2 | L14: =J4^2+J5^2+J6^2+J7^2+J8^2+J9^2+J10^2 -> 85.25 | M14: ȳ | N14: =AVERAGE(L4:L10) -> 0.16383333
A15: 12 | B15: =Cadastro!A14 -> 2025/20 | C15: 0.005 | D15: 50 | E15: 10 | F15: 0.0636 | G15: =((F15-M$18)/M$17)*E15*D15/1000/C15/120 -> 0.5929539 | J15: (∑x)2 | L15: =SUM(J4:J10)^2 -> 240.25 | M15: x | N15: =AVERAGE(J4:J10) -> 2.5833333
A16: 13 | B16: =Cadastro!A15 -> 2025/21 | C16: 0.005 | D16: 50 | E16: 10 | F16: 0.1576 | G16: =((F16-M$18)/M$17)*E16*D16/1000/C16/120 -> 2.0557751 | J16: ∑y | L16: =SUM(L4:L10) -> 0.983
A17: 14 | B17: =Cadastro!A16 -> 2025/22 | C17: 0.005 | D17: 50 | E17: 10 | F17: 0.1367 | G17: =((F17-M$18)/M$17)*E17*D17/1000/C17/120 -> 1.7305308 | L17: b | M17: =(N13-(L13*L16/6))/((L14-(L15/6))) -> 0.053549493
L18: a | M18: =N14-(M17*N15) -> 0.025497143
K31: esta faltando trans

Sheet Cu
B1: Determinação de teores disponiveis de Cu em Melich -1
A2: N° | B2: N_Lab | C2: V-solo (dm3) | D2: V-extrator (mL) | E2: Diluição (nx) | F2: Emissão (u.a) | G2: Cu-disponivel (mg/dm3) | J2: Curva de Calibração
A3: * | B3: =Cadastro!A2 -> * | J3: Cu_mg/L | K3: Abs% | L3: x*y
A4: 1 | B4: =Cadastro!A3 -> Padrão A | C4: 0.005 | D4: 50 | E4: 1 | F4: - | G4: 0.93 | J4: 0 | K4: 0 | L4: =J4*K4 -> 0
A5: 2 | B5: =Cadastro!A4 -> Padrão B | C5: 0.005 | D5: 50 | E5: 1 | F5: 0.0892 | G5: 0.45 | J5: 0.4 | K5: 0.005 | L5: =J5*K5 -> 0.002
A6: 3 | B6: =Cadastro!A5 -> P. Labas A | C6: 0.005 | D6: 50 | E6: 1 | F6: 0.0013 | G6: =((F6-L$17)/L$16)*E6*D6/1000/C6 -> 1.108871 | J6: 0.8 | K6: 0.0111 | L6: =J6*K6 -> 0.00888
A7: 4 | B7: =Cadastro!A6 -> P. Labas B | C7: 0.005 | D7: 50 | E7: 1 | F7: 0.0007 | G7: =((F7-L$17)/L$16)*E7*D7/1000/C7 -> 0.68548387 | J7: 1.2 | K7: 0.0169 | L7: =J7*K7 -> 0.02028
A8: 5 | B8: =Cadastro!A7 -> 2025/13 | C8: 0.005 | D8: 50 | E8: 1 | F8: 0.0021 | G8: =((F8-L$17)/L$16)*E8*D8/1000/C8 -> 1.6733871 | J8: 1.6 | K8: 0.0222 | L8: =J8*K8 -> 0.03552
A9: 6 | B9: =Cadastro!A8 -> 2025/14 | C9: 0.005 | D9: 50 | E9: 1 | F9: 0.0016 | G9: =((F9-L$17)/L$16)*E9*D9/1000/C9 -> 1.3205645 | J9: 2 | K9: 0.0282 | L9: =J9*K9 -> 0.0564
A10: 7 | B10: =Cadastro!A9 -> 2025/15 | C10: 0.005 | D10: 50 | E10: 1 | F10: 0.0061 | G10: =((F10-L$17)/L$16)*E10*D10/1000/C10 -> 4.4959677 | K10: ∑x.y | L10: =SUM(L4:L9) -> 0.12308
A11: 8 | B11: =Cadastro!A10 -> 2025/16 | C11: 0.005 | D11: 50 | E11: 1 | F11: 0.0072 | G11: =((F11-L$17)/L$16)*E11*D11/1000/C11 -> 5.2721774
A12: 9 | B12: =Cadastro!A11 -> 2025/17 | C12: 0.005 | D12: 50 | E12: 1 | F12: 0.0068 | G12: =((F12-L$17)/L$16)*E12*D12/1000/C12 -> 4.9899194 | J12: ∑x | K12: =SUM(J4:J9) -> 6 | L12: ∑xy | M12: =L10 -> 0.12308
A13: 10 | B13: =Cadastro!A12 -> 2025/18 | C13: 0.005 | D13: 50 | E13: 1 | F13: 0.0113 | G13: =((F13-L$17)/L$16)*E13*D13/1000/C13 -> 8.1653226 | J13: ∑x2 | K13: =J4^2+J5^2+J6^2+J7^2+J8^2+J9^2 -> 8.8 | L13: ȳ | M13: =AVERAGE(K4:K9) -> 0.0139
A14: 11 | B14: =Cadastro!A13 -> 2025/19 | C14: 0.005 | D14: 50 | E14: 1 | F14: 0.001 | G14: =((F14-L$17)/L$16)*E14*D14/1000/C14 -> 0.89717742 | J14: (∑x)2 | K14: =SUM(J4:J9)^2 -> 36 | L14: x | M14: =AVERAGE(J4:J9) -> 1
A15: 12 | B15: =Cadastro!A14 -> 2025/20 | C15: 0.005 | D15: 50 | E15: 1 | F15: 0.001 | G15: =((F15-L$17)/L$16)*E15*D15/1000/C15 -> 0.89717742 | J15: ∑y | K15: =SUM(K4:K9) -> 0.0834
A16: 13 | B16: =Cadastro!A15 -> 2025/21 | C16: 0.005 | D16: 50 | E16: 1 | F16: 0.0008 | G16: =((F16-L$17)/L$16)*E16*D16/1000/C16 -> 0.75604839 | K16: b | L16: =(M12-(K12*K15/6))/((K13-(K14/6))) -> 0.014171429
A17: 14 | B17: =Cadastro!A16 -> 2025/22 | C17: 0.005 | D17: 50 | E17: 1 | F17: 0.0008 | G17: =((F17-L$17)/L$16)*E17*D17/1000/C17 -> 0.75604839 | K17: a | L17: =M13-(L16*M14) -> -0.00027142857

Sheet Fe
B1: Determinação de teores disponiveis de Fe em Melich -1
A2: N° | B2: N_Lab | C2: V-solo (dm3) | D2: V-extrator (mL) | E2: Diluição (nx) | F2: Emissão (u.a) | G2: Fe-disponivel (mg/dm3) | J2: Curva de Calibração
A3: * | B3: =Cadastro!A2 -> * | J3: Fe_mg/L | K3: Abs% | L3: x*y
A4: 1 | B4: =Cadastro!A3 -> Padrão A | C4: 0.005 | D4: 50 | E4: 1 | F4: - | G4: 39.4 | J4: 0 | K4: -0.0003 | L4: =J4*K4 -> 0
A5: 2 | B5: =Cadastro!A4 -> Padrão B | C5: 0.005 | D5: 50 | E5: 1 | F5: 0.0251 | G5: 15.5 | J5: 3 | K5: 0.0226 | L5: =J5*K5 -> 0.0678
A6: 3 | B6: =Cadastro!A5 -> P. Labas A | C6: 0.005 | D6: 50 | E6: 1 | F6: 0.0316 | G6: =((F6-L$17)/L$16)*E6*D6/1000/C6 -> 42.942373 | J6: 6 | K6: 0.0456 | L6: =J6*K6 -> 0.2736
A7: 4 | B7: =Cadastro!A6 -> P. Labas B | C7: 0.005 | D7: 50 | E7: 1 | F7: 0.0231 | G7: =((F7-L$17)/L$16)*E7*D7/1000/C7 -> 30.840678 | J7: 9 | K7: 0.0657 | L7: =J7*K7 -> 0.5913
A8: 5 | B8: =Cadastro!A7 -> 2025/13 | C8: 0.005 | D8: 50 | E8: 1 | F8: 0.0199 | G8: =((F8-L$17)/L$16)*E8*D8/1000/C8 -> 26.284746 | J8: 12 | K8: 0.0859 | L8: =J8*K8 -> 1.0308
A9: 6 | B9: =Cadastro!A8 -> 2025/14 | C9: 0.005 | D9: 50 | E9: 1 | F9: 0.013 | G9: =((F9-L$17)/L$16)*E9*D9/1000/C9 -> 16.461017 | J9: 15 | K9: 0.1052 | L9: =J9*K9 -> 1.578
A10: 7 | B10: =Cadastro!A9 -> 2025/15 | C10: 0.005 | D10: 50 | E10: 1 | F10: 0.0194 | G10: =((F10-L$17)/L$16)*E10*D10/1000/C10 -> 25.572881 | K10: ∑x.y | L10: =SUM(L4:L9) -> 3.5415
A11: 8 | B11: =Cadastro!A10 -> 2025/16 | C11: 0.005 | D11: 50 | E11: 1 | F11: 0.0202 | G11: =((F11-L$17)/L$16)*E11*D11/1000/C11 -> 26.711864
A12: 9 | B12: =Cadastro!A11 -> 2025/17 | C12: 0.005 | D12: 50 | E12: 1 | F12: 0.0249 | G12: =((F12-L$17)/L$16)*E12*D12/1000/C12 -> 33.40339 | J12: ∑x | K12: =SUM(J4:J9) -> 45 | L12: ∑xy | M12: =L10 -> 3.5415
A13: 10 | B13: =Cadastro!A12 -> 2025/18 | C13: 0.005 | D13: 50 | E13: 1 | F13: 0.0368 | G13: =((F13-L$17)/L$16)*E13*D13/1000/C13 -> 50.345763 | J13: ∑x2 | K13: =J4^2+J5^2+J6^2+J7^2+J8^2+J9^2 -> 495 | L13: ȳ | M13: =AVERAGE(K4:K9) -> 0.054116667
A14: 11 | B14: =Cadastro!A13 -> 2025/19 | C14: 0.005 | D14: 50 | E14: 1 | F14: 0.0292 | G14: =((F14-L$17)/L$16)*E14*D14/1000/C14 -> 39.525424 | J14: (∑x)2 | K14: =SUM(J4:J9)^2 -> 2025 | L14: x | M14: =AVERAGE(J4:J9) -> 7.5
A15: 12 | B15: =Cadastro!A14 -> 2025/20 | C15: 0.005 | D15: 50 | E15: 1 | F15: 0.0333 | G15: =((F15-L$17)/L$16)*E15*D15/1000/C15 -> 45.362712 | J15: ∑y | K15: =SUM(K4:K9) -> 0.3247
A16: 13 | B16: =Cadastro!A15 -> 2025/21 | C16: 0.005 | D16: 50 | E16: 1 | F16: 0.0405 | G16: =((F16-L$17)/L$16)*E16*D16/1000/C16 -> 55.613559 | K16: b | L16: =(M12-(K12*K15/6))/((K13-(K14/6))) -> 0.0070238095
A17: 14 | B17: =Cadastro!A16 -> 2025/22 | C17: 0.005 | D17: 50 | E17: 1 | F17: 0.0348 | G17: =((F17-L$17)/L$16)*E17*D17/1000/C17 -> 47.498305 | K17: a | L17: =M13-(L16*M14) -> 0.0014380952

Sheet Mn
B1: Determinação de teores disponiveis de Mn em Melich -1
A2: N° | B2: N_Lab | C2: V-solo (dm3) | D2: V-extrator (mL) | E2: Diluição (nx) | F2: Emissão (u.a) | G2: Mn-disponivel (mg/dm3) | J2: Curva de Calibração
A3: * | B3: =Cadastro!A2 -> * | J3: Mn_mg/L | K3: Abs% | L3: x*y
A4: 1 | B4: =Cadastro!A3 -> Padrão A | C4: 0.005 | D4: 50 | E4: 1 | F4: - | G4: 1.4 | J4: 0 | K4: -0.0003 | L4: =J4*K4 -> 0
A5: 2 | B5: =Cadastro!A4 -> Padrão B | C5: 0.005 | D5: 50 | E5: 1 | F5: 0.0636 | G5: 10.2 | J5: 1 | K5: 0.0182 | L5: =J5*K5 -> 0.0182
A6: 3 | B6: =Cadastro!A5 -> P. Labas A | C6: 0.005 | D6: 50 | E6: 1 | F6: 0.0044 | G6: =((F6-L$17)/L$16)*E6*D6/1000/C6 -> 2.2993974 | J6: 2 | K6: 0.0369 | L6: =J6*K6 -> 0.0738
A7: 4 | B7: =Cadastro!A6 -> P. Labas B | C7: 0.005 | D7: 50 | E7: 1 | F7: 0.032 | G7: =((F7-L$17)/L$16)*E7*D7/1000/C7 -> 17.618141 | J7: 3 | K7: 0.055 | L7: =J7*K7 -> 0.165
A8: 5 | B8: =Cadastro!A7 -> 2025/13 | C8: 0.005 | D8: 50 | E8: 1 | F8: 0.0674 | G8: =((F8-L$17)/L$16)*E8*D8/1000/C8 -> 37.266096 | J8: 4 | K8: 0.0722 | L8: =J8*K8 -> 0.2888
A9: 6 | B9: =Cadastro!A8 -> 2025/14 | C9: 0.005 | D9: 50 | E9: 1 | F9: 0.0333 | G9: =((F9-L$17)/L$16)*E9*D9/1000/C9 -> 18.339676 | J9: 5 | K9: 0.0898 | L9: =J9*K9 -> 0.449
A10: 7 | B10: =Cadastro!A9 -> 2025/15 | C10: 0.005 | D10: 50 | E10: 1 | F10: 0.0322 | G10: =((F10-L$17)/L$16)*E10*D10/1000/C10 -> 17.729147 | K10: ∑x.y | L10: =SUM(L4:L9) -> 0.9948
A11: 8 | B11: =Cadastro!A10 -> 2025/16 | C11: 0.005 | D11: 50 | E11: 1 | F11: 0.0471 | G11: =((F11-L$17)/L$16)*E11*D11/1000/C11 -> 25.999049
A12: 9 | B12: =Cadastro!A11 -> 2025/17 | C12: 0.005 | D12: 50 | E12: 1 | F12: 0.093 | G12: =((F12-L$17)/L$16)*E12*D12/1000/C12 -> 51.474786 | J12: ∑x | K12: =SUM(J4:J9) -> 15 | L12: ∑xy | M12: =L10 -> 0.9948
A13: 10 | B13: =Cadastro!A12 -> 2025/18 | C13: 0.005 | D13: 50 | E13: 1 | F13: 0.0547 | G13: =((F13-L$17)/L$16)*E13*D13/1000/C13 -> 30.217253 | J13: ∑x2 | K13: =J4^2+J5^2+J6^2+J7^2+J8^2+J9^2 -> 55 | L13: ȳ | M13: =AVERAGE(K4:K9) -> 0.0453
A14: 11 | B14: =Cadastro!A13 -> 2025/19 | C14: 0.005 | D14: 50 | E14: 1 | F14: 0.2524 | G14: =((F14-L$17)/L$16)*E14*D14/1000/C14 -> 139.94608 | J14: (∑x)2 | K14: =SUM(J4:J9)^2 -> 225 | L14: x | M14: =AVERAGE(J4:J9) -> 2.5
A15: 12 | B15: =Cadastro!A14 -> 2025/20 | C15: 0.005 | D15: 50 | E15: 1 | F15: 0.1586 | G15: =((F15-L$17)/L$16)*E15*D15/1000/C15 -> 87.884554 | J15: ∑y | K15: =SUM(K4:K9) -> 0.2718
A16: 13 | B16: =Cadastro!A15 -> 2025/21 | C16: 0.005 | D16: 50 | E16: 1 | F16: 0.1878 | G16: =((F16-L$17)/L$16)*E16*D16/1000/C16 -> 104.09134 | K16: b | L16: =(M12-(K12*K15/6))/((K13-(K14/6))) -> 0.018017143
A17: 14 | B17: =Cadastro!A16 -> 2025/22 | C17: 0.005 | D17: 50 | E17: 1 | F17: 0.1025 | G17: =((F17-L$17)/L$16)*E17*D17/1000/C17 -> 56.747542 | K17: a | L17: =M13-(L16*M14) -> 0.00025714286

Sheet Zn
B1: Determinação de teores disponiveis de Zn em Melich -1
A2: N° | B2: N_Lab | C2: V-solo (dm3) | D2: V-extrator (mL) | E2: Diluição (nx) | F2: Emissão (u.a) | G2: Zn-disponivel (mg/dm3) | J2: Curva de Calibração
A3: * | B3: =Cadastro!A2 -> * | J3: Zn_mg/L | K3: Abs% | L3: x*y
A4: 1 | B4: =Cadastro!A3 -> Padrão A | C4: 0.005 | D4: 50 | E4: 1 | F4: - | G4: 0.18 | J4: 0 | K4: 0 | L4: =J4*K4 -> 0
A5: 2 | B5: =Cadastro!A4 -> Padrão B | C5: 0.005 | D5: 50 | E5: 1 | F5: 0.0064 | G5: 2.26 | J5: 0.4 | K5: 0.0233 | L5: =J5*K5 -> 0.00932
A6: 3 | B6: =Cadastro!A5 -> P. Labas A | C6: 0.005 | D6: 50 | E6: 1 | F6: 0.0009 | G6: =((F6)/L$16)*E6*D6/1000/C6 -> 0.16682113 | J6: 0.8 | K6: 0.0463 | L6: =J6*K6 -> 0.03704
A7: 4 | B7: =Cadastro!A6 -> P. Labas B | C7: 0.005 | D7: 50 | E7: 1 | F7: 0.0111 | G7: =((F7-L$17)/L$16)*E7*D7/1000/C7 -> 1.7732468 | J7: 1.2 | K7: 0.0671 | L7: =J7*K7 -> 0.08052
A8: 5 | B8: =Cadastro!A7 -> 2025/13 | C8: 0.005 | D8: 50 | E8: 1 | F8: 0.053 | G8: =((F8-L$17)/L$16)*E8*D8/1000/C8 -> 9.5396973 | J8: 1.6 | K8: 0.0883 | L8: =J8*K8 -> 0.14128
A9: 6 | B9: =Cadastro!A8 -> 2025/14 | C9: 0.005 | D9: 50 | E9: 1 | F9: 0.0346 | G9: =((F9-L$17)/L$16)*E9*D9/1000/C9 -> 6.1291319 | J9: 2 | K9: 0.1079 | L9: =J9*K9 -> 0.2158
A10: 7 | B10: =Cadastro!A9 -> 2025/15 | C10: 0.005 | D10: 50 | E10: 1 | F10: 0.0564 | G10: =((F10-L$17)/L$16)*E10*D10/1000/C10 -> 10.16991 | K10: ∑x.y | L10: =SUM(L4:L9) -> 0.48396
A11: 8 | B11: =Cadastro!A10 -> 2025/16 | C11: 0.005 | D11: 50 | E11: 1 | F11: 0.0861 | G11: =((F11-L$17)/L$16)*E11*D11/1000/C11 -> 15.675008
A12: 9 | B12: =Cadastro!A11 -> 2025/17 | C12: 0.005 | D12: 50 | E12: 1 | F12: 0.1515 | G12: =((F12-L$17)/L$16)*E12*D12/1000/C12 -> 27.797343 | J12: ∑x | K12: =SUM(J4:J9) -> 6 | L12: ∑xy | M12: =L10 -> 0.48396
A13: 10 | B13: =Cadastro!A12 -> 2025/18 | C13: 0.005 | D13: 50 | E13: 1 | F13: 0.1245 | G13: =((F13-L$17)/L$16)*E13*D13/1000/C13 -> 22.792709 | J13: ∑x2 | K13: =J4^2+J5^2+J6^2+J7^2+J8^2+J9^2 -> 8.8 | L13: ȳ | M13: =AVERAGE(K4:K9) -> 0.055483333
A14: 11 | B14: =Cadastro!A13 -> 2025/19 | C14: 0.005 | D14: 50 | E14: 1 | F14: 0.0108 | G14: =((F14-L$17)/L$16)*E14*D14/1000/C14 -> 1.7176398 | J14: (∑x)2 | K14: =SUM(J4:J9)^2 -> 36 | L14: x | M14: =AVERAGE(J4:J9) -> 1
A15: 12 | B15: =Cadastro!A14 -> 2025/20 | C15: 0.005 | D15: 50 | E15: 1 | F15: 0.0078 | G15: =((F15-L$17)/L$16)*E15*D15/1000/C15 -> 1.1615694 | J15: ∑y | K15: =SUM(K4:K9) -> 0.3329
A16: 13 | B16: =Cadastro!A15 -> 2025/21 | C16: 0.005 | D16: 50 | E16: 1 | F16: 0.0134 | G16: =((F16-L$17)/L$16)*E16*D16/1000/C16 -> 2.1995675 | K16: b | L16: =(M12-(K12*K15/6))/((K13-(K14/6))) -> 0.05395
A17: 14 | B17: =Cadastro!A16 -> 2025/22 | C17: 0.005 | D17: 50 | E17: 1 | F17: 0.0101 | G17: =((F17-L$17)/L$16)*E17*D17/1000/C17 -> 1.58789 | K17: a | L17: =M13-(L16*M14) -> 0.0015333333

Sheet Absorção atômica
A1: Sample | B1: Ca | C1: Mg | D1: Cu | E1: Fe | F1: Mn | G1: Zn | I1: Ca | J1: Mg | K1: Cu | L1: Fe | M1: Mn | N1: Zn
A2: (Mean | B2: g/kg | C2: g/kg | D2: mg/kg | E2: mg/kg | F2: mg/kg | G2: mg/kg | I2: g/kg | J2: g/kg | K2: mg/kg | L2: mg/kg | M2: mg/kg | N2: mg/kg
A3: Branco | B3: 0.2206 | C3: 0.0222 | D3: -0.0005 | E3: 0.0004 | F3: -0.0015 | G3: 0.004
A4: PA | B4: 0.23 | C4: 0.0244 | D4: 0.0008 | E4: 0.032 | F4: 0.0029 | G4: 0.0049 | I4: =B4-B$3 -> 0.0094 | J4: =C4-C$3 -> 0.0022 | K4: =D4-D$3 -> 0.0013 | L4: =E4-E$3 -> 0.0316 | M4: =F4-F$3 -> 0.0044 | N4: =G4-G$3 -> 0.0009
A5: PB | B5: 0.647 | C5: 0.1221 | D5: 0.0002 | E5: 0.0235 | F5: 0.0305 | G5: 0.0151 | I5: =B5-B$3 -> 0.4264 | J5: =C5-C$3 -> 0.0999 | K5: =D5-D$3 -> 0.0007 | L5: =E5-E$3 -> 0.0231 | M5: =F5-F$3 -> 0.032 | N5: =G5-G$3 -> 0.0111
A6: 1 | B6: 0.3937 | C6: 0.0769 | D6: 0.0016 | E6: 0.0203 | F6: 0.0659 | G6: 0.057 | I6: =B6-B$3 -> 0.1731 | J6: =C6-C$3 -> 0.0547 | K6: =D6-D$3 -> 0.0021 | L6: =E6-E$3 -> 0.0199 | M6: =F6-F$3 -> 0.0674 | N6: =G6-G$3 -> 0.053
A7: 2 | B7: 0.4502 | C7: 0.0679 | D7: 0.0011 | E7: 0.0134 | F7: 0.0318 | G7: 0.0386 | I7: =B7-B$3 -> 0.2296 | J7: =C7-C$3 -> 0.0457 | K7: =D7-D$3 -> 0.0016 | L7: =E7-E$3 -> 0.013 | M7: =F7-F$3 -> 0.0333 | N7: =G7-G$3 -> 0.0346
A8: 3 | B8: 0.4533 | C8: 0.0626 | D8: 0.0056 | E8: 0.0198 | F8: 0.0307 | G8: 0.0604 | I8: =B8-B$3 -> 0.2327 | J8: =C8-C$3 -> 0.0404 | K8: =D8-D$3 -> 0.0061 | L8: =E8-E$3 -> 0.0194 | M8: =F8-F$3 -> 0.0322 | N8: =G8-G$3 -> 0.0564
A9: 4 | B9: 0.4766 | C9: 0.071 | D9: 0.0067 | E9: 0.0206 | F9: 0.0456 | G9: 0.0901 | I9: =B9-B$3 -> 0.256 | J9: =C9-C$3 -> 0.0488 | K9: =D9-D$3 -> 0.0072 | L9: =E9-E$3 -> 0.0202 | M9: =F9-F$3 -> 0.0471 | N9: =G9-G$3 -> 0.0861
A10: 5 | B10: 0.5491 | C10: 0.0825 | D10: 0.0063 | E10: 0.0253 | F10: 0.0915 | G10: 0.1555 | I10: =B10-B$3 -> 0.3285 | J10: =C10-C$3 -> 0.0603 | K10: =D10-D$3 -> 0.0068 | L10: =E10-E$3 -> 0.0249 | M10: =F10-F$3 -> 0.093 | N10: =G10-G$3 -> 0.1515
A11: 6 | B11: 0.4923 | C11: 0.0566 | D11: 0.0108 | E11: 0.0372 | F11: 0.0532 | G11: 0.1285 | I11: =B11-B$3 -> 0.2717 | J11: =C11-C$3 -> 0.0344 | K11: =D11-D$3 -> 0.0113 | L11: =E11-E$3 -> 0.0368 | M11: =F11-F$3 -> 0.0547 | N11: =G11-G$3 -> 0.1245
A12: 7 | B12: 0.6195 | C12: 0.0956 | D12: 0.0005 | E12: 0.0296 | F12: 0.2509 | G12: 0.0148 | I12: =B12-B$3 -> 0.3989 | J12: =C12-C$3 -> 0.0734 | K12: =D12-D$3 -> 0.001 | L12: =E12-E$3 -> 0.0292 | M12: =F12-F$3 -> 0.2524 | N12: =G12-G$3 -> 0.0108
A13: 8 | B13: 0.4602 | C13: 0.0858 | D13: 0.0005 | E13: 0.0337 | F13: 0.1571 | G13: 0.0118 | I13: =B13-B$3 -> 0.2396 | J13: =C13-C$3 -> 0.0636 | K13: =D13-D$3 -> 0.001 | L13: =E13-E$3 -> 0.0333 | M13: =F13-F$3 -> 0.1586 | N13: =G13-G$3 -> 0.0078
A14: 9 | B14: 1.0946 | C14: 0.1798 | D14: 0.0003 | E14: 0.0409 | F14: 0.1863 | G14: 0.0174 | I14: =B14-B$3 -> 0.874 | J14: =C14-C$3 -> 0.1576 | K14: =D14-D$3 -> 0.0008 | L14: =E14-E$3 -> 0.0405 | M14: =F14-F$3 -> 0.1878 | N14: =G14-G$3 -> 0.0134
A15: 10 | B15: 0.965 | C15: 0.1589 | D15: 0.0003 | E15: 0.0352 | F15: 0.101 | G15: 0.0141 | I15: =B15-B$3 -> 0.7444 | J15: =C15-C$3 -> 0.1367 | K15: =D15-D$3 -> 0.0008 | L15: =E15-E$3 -> 0.0348 | M15: =F15-F$3 -> 0.1025 | N15: =G15-G$3 -> 0.0101
O24: absorcao atomica é onde inserem os valores brutos
O25: subtraem o branco e podem ser inseridos nas abas | S25: individuais
M27: site da prefeitura nota
O29: ter um campo de inserir os dados do cliente e enviar o relatorio no email e whatsapp

Sheet Planilha mestra
B1: 1 | C1: 2 | D1: 3 | E1: 4 | F1: 5 | G1: 6 | H1: 7 | I1: 8 | J1: 9 | K1: 10 | L1: 11 | M1: 12 | N1: 13 | O1: 14 | P1: 15 | Q1: 16 | R1: 17 | S1: 18 | T1: 19 | U1: 20 | V1: 21 | W1: 22 | X1: 23 | Y1: 24 | Z1: 25 | AA1: 26 | AB1: 27 | AC1: 28 | AD1: 29
A2: N Lab | B2: Código cliente | C2: pH água | D2: pH Kcl | E2: pH Cacl2 | F2: P_M | G2: P_R | H2: K | I2: Na | J2: Ca | K2: Mg2+ | L2: Al3+ | M2: H+Al | N2: SB | O2: t | P2: T | Q2: V | R2: m | S2: P-rem | T2: S | U2: B | V2: Zn | W2: Cu | X2: Mn | Y2: Fe | Z2: MO | AA2: Ca/Mg | AB2: Ca/K | AC2: Mg/K | AD2: C-org
A3: =Cadastro!A2 -> * | B3: =Cadastro!E2 -> * | C3: * | D3: * | E3: * | F3: * | G3: * | H3: * | I3: * | J3: * | K3: * | L3: * | M3: * | N3: * | O3: * | P3: * | Q3: * | R3: * | S3: * | T3: * | U3: * | V3: * | W3: * | X3: * | Y3: * | Z3: * | AA3: * | AB3: * | AC3: *
A4: =Cadastro!A5 -> P. Labas A | B4: =Cadastro!E5 -> Padrão A | C4: =pH_água!C5 -> 4.8073333 | D4: =pH_KCl!C5 -> * | E4: * | F4: =P_Mehlich1!H6 -> 0.57159491 | G4: =P_resina!H6 -> #VALUE! | H4: =K!G6 -> 1.5108593 | I4: * | J4: ='Ca2+'!G6 -> 0.11530887 | K4: =Mg²!G6 -> 0.034236241 | L4: =Al³!C6 -> 0.39 | M4: ='H + Al'!C6 -> 1.2123555 | N4: =(H4/390)+J4+K4 -> 0.1534191 | O4: =N4+L4 -> 0.5434191 | P4: =N4+M4 -> 1.3657746 | Q4: =(N4/P4)*100 -> 11.23312 | R4: =(L4/O4)*100 -> 71.767812 | S4: =Prem!H6 -> 39.792952 | T4: =S!H6 -> 24.791177 | U4: =B!H6 -> 0.0079106241 | V4: =Zn!G6 -> 0.16682113 | W4: =Cu!G6 -> 1.108871 | X4: =Mn!G6 -> 2.2993974 | Y4: =Fe!G6 -> 42.942373 | Z4: =M.O!H6 -> 0.59332131 | AA4: =J4/K4 -> 3.3680353 | AB4: =J4/(H4/390) -> 29.764822 | AC4: =K4/(H4/390) -> 8.8374436 | AD4: =Z4/1.72 -> 0.34495425
A5: =Cadastro!A6 -> P. Labas B | B5: =Cadastro!E6 -> Padrão B | C5: =pH_água!C6 -> 6.707907 | D5: =pH_KCl!C6 -> * | E5: ='pH CaCl2'!C6 -> * | F5: =P_Mehlich1!H7 -> 3.7937907 | G5: =P_resina!H7 -> #VALUE! | H5: =K!G7 -> 37.20491 | I5: * | J5: ='Ca2+'!G7 -> 4.965361 | K5: =Mg²!G7 -> 1.1578519 | L5: =Al³!C7 -> 0.5 | M5: ='H + Al'!C7 -> 1.4718719 | N5: =(H5/390)+J5+K5 -> 6.2186101 | O5: =N5+L5 -> 6.7186101 | P5: =N5+M5 -> 7.6904819 | Q5: =(N5/P5)*100 -> 80.861123 | R5: =(L5/O5)*100 -> 7.4420155 | S5: =Prem!H7 -> #VALUE! | T5: =S!H7 -> 1.3318784 | U5: =B!H7 -> 0.28852014 | V5: =Zn!G7 -> 1.7732468 | W5: =Cu!G7 -> 0.68548387 | X5: =Mn!G7 -> 17.618141 | Y5: =Fe!G7 -> 30.840678 | Z5: =M.O!H7 -> 2.8732588 | AA5: =J5/K5 -> 4.2884251 | AB5: =J5/(H5/390) -> 52.049334 | AC5: =K5/(H5/390) -> 12.137168 | AD5: =Z5/1.72 -> 1.6704993
A6: =Cadastro!A7 -> 2025/13 | B6: =Cadastro!E7 -> Carlos Ace | C6: =pH_água!C7 -> 5.8135194 | D6: =pH_KCl!C7 -> * | E6: ='pH CaCl2'!C7 -> * | F6: =P_Mehlich1!H8 -> 137.11124 | G6: =P_resina!H8 -> 219.04025 | H6: =K!G8 -> 51.08593 | J6: ='Ca2+'!G8 -> 1.8581551 | K6: =Mg²!G8 -> 0.45445275 | L6: =Al³!C8 -> 0.48 | M6: ='H + Al'!C8 -> 1.4718719 | N6: =(H6/390)+J6+K6 -> 2.4435974 | O6: =N6+L6 -> 2.9235974 | P6: =N6+M6 -> 3.9154692 | Q6: =(N6/P6)*100 -> 62.4088 | R6: =(L6/O6)*100 -> 16.418129 | S6: =Prem!H8 -> #VALUE! | T6: =S!H8 -> 12.935637 | U6: =B!H8 -> 0.066230959 | V6: =Zn!G8 -> 9.5396973 | W6: =Cu!G8 -> 1.6733871 | X6: =Mn!G8 -> 37.266096 | Y6: =Fe!G8 -> 26.284746 | Z6: =M.O!H8 -> 0.98886924 | AA6: =J6/K6 -> 4.0887751 | AB6: =J6/(H6/390) -> 14.18552 | AC6: =K6/(H6/390) -> 3.4693813 | AD6: =Z6/1.72 -> 0.57492397
A7: =Cadastro!A8 -> 2025/14 | B7: =Cadastro!E8 -> Carlos Amostra | C7: =pH_água!C8 -> 6.1302817 | D7: =pH_KCl!C8 -> * | E7: ='pH CaCl2'!C8 -> * | F7: =P_Mehlich1!H9 -> 127.99163 | G7: =P_resina!H9 -> 287.92272 | H7: =K!G9 -> 64.96695 | I7: * | J7: ='Ca2+'!G9 -> 2.5512349 | K7: =Mg²!G9 -> 0.3143954 | L7: =Al³!C9 -> 0 | M7: ='H + Al'!C9 -> 0.49433345 | N7: =(H7/390)+J7+K7 -> 3.0322123 | O7: =N7+L7 -> 3.0322123 | P7: =N7+M7 -> 3.5265457 | Q7: =(N7/P7)*100 -> 85.982503 | R7: =(L7/O7)*100 -> 0 | S7: =Prem!H9 -> 51.979629 | T7: =S!H9 -> 1.2480037 | U7: =B!H9 -> 0.043906115 | V7: =Zn!G9 -> 6.1291319 | W7: =Cu!G9 -> 1.3205645 | X7: =Mn!G9 -> 18.339676 | Y7: =Fe!G9 -> 16.461017 | Z7: =M.O!H9 -> 0.7027526 | AA7: =J7/K7 -> 8.1147337 | AB7: =J7/(H7/390) -> 15.315197 | AC7: =K7/(H7/390) -> 1.887332 | AD7: =Z7/1.72 -> 0.40857709
A8: =Cadastro!A9 -> 2025/15 | B8: =Cadastro!E9 -> Rubens alface 1 | C8: =pH_água!C9 -> 6.1209651 | D8: =pH_KCl!C9 -> * | E8: ='pH CaCl2'!C9 -> * | F8: =P_Mehlich1!H10 -> 179.10733 | G8: =P_resina!H10 -> #VALUE! | H8: =K!G10 -> 33.238905 | I8: * | J8: ='Ca2+'!G10 -> 2.5892623 | K8: =Mg²!G10 -> 0.23191718 | L8: =Al³!C10 -> 0 | M8: ='H + Al'!C10 -> 0.84271359 | N8: =(H8/390)+J8+K8 -> 2.9064075 | O8: =N8+L8 -> 2.9064075 | P8: =N8+M8 -> 3.7491211 | Q8: =(N8/P8)*100 -> 77.522369 | R8: =(L8/O8)*100 -> 0 | S8: =Prem!H10 -> 39.792952 | T8: =S!H10 -> 0.74653652 | U8: =B!H10 -> 0.035850194 | V8: =Zn!G10 -> 10.16991 | W8: =Cu!G10 -> 4.4959677 | X8: =Mn!G10 -> 17.729147 | Y8: =Fe!G10 -> 25.572881 | Z8: =M.O!H10 -> 0.61888959 | AA8: =J8/K8 -> 11.164599 | AB8: =J8/(H8/390) -> 30.380433 | AC8: =K8/(H8/390) -> 2.7211397 | AD8: =Z8/1.72 -> 0.35981953
A9: =Cadastro!A10 -> 2025/16 | B9: =Cadastro!E10 -> Rubens Alface 2 | C9: =pH_água!C10 -> 6.2420801 | D9: =pH_KCl!C10 -> * | E9: ='pH CaCl2'!C10 -> * | F9: =P_Mehlich1!H11 -> 172.84153 | G9: =P_resina!H11 -> #VALUE! | H9: =K!G11 -> 120.49103 | I9: * | J9: ='Ca2+'!G11 -> 2.8750811 | K9: =Mg²!G11 -> 0.36263738 | L9: =Al³!C11 -> 0 | M9: ='H + Al'!C11 -> 0.82252669 | N9: =(H9/390)+J9+K9 -> 3.5466699 | O9: =N9+L9 -> 3.5466699 | P9: =N9+M9 -> 4.3691965 | Q9: =(N9/P9)*100 -> 81.174418 | R9: =(L9/O9)*100 -> 0 | S9: =Prem!H11 -> 29.283468 | T9: =S!H11 -> 0.24809635 | U9: =B!H11 -> 0.090876832 | V9: =Zn!G11 -> 15.675008 | W9: =Cu!G11 -> 5.2721774 | X9: =Mn!G11 -> 25.999049 | Y9: =Fe!G11 -> 26.711864 | Z9: =M.O!H11 -> 0.78781303 | AA9: =J9/K9 -> 7.9282537 | AB9: =J9/(H9/390) -> 9.3059346 | AC9: =K9/(H9/390) -> 1.1737685 | AD9: =Z9/1.72 -> 0.45803083
